Workbook

Sheet PPC ANALISIS
D2: NOMBRE DE PROYECTO : | I2: =Carátula!C10 -> “REPOSICIÓN DEL SISTEMA DE DOSIFICACIÓN DE FLOCULANTE”
D3: SEMANA DE ANALISIS : | I3: =Carátula!C17 -> 33
D4: PORCENTAJE DE PLAN CUMPLIDO PAC: | I4: =D35 -> 0.55555556
D5: PORCENTAJE DE PLAN CUMPLIDO PAE: | I5: =D36 -> 0 | AP5: MY
AL6: =IF(AC6>0,IF(AK6>=AC6,"SÍ","NO"),IF(AND(AC6=0,AK6=0)," ","ENP"))
B9: SEMANA | C9: PPC SEMANAL | D9: PPC META
B10: 27 | C10: =IF($I$3=27,$D$35,"") | D10: 0.8
B11: 28 | C11: =IF($I$3=28,$D$35,"") | D11: 0.8
B12: 29 | C12: =IF($I$3=29,$D$35,"") | D12: 0.8
B13: 30 | C13: =IF($I$3=30,$D$35,"") | D13: 0.8
B14: 31 | C14: =IF($I$3=31,$D$35,"") | D14: 0.8
B15: 32 | C15: =IF($I$3=32,$D$35,"") | D15: 0.8
B16: 33 | C16: =IF($I$3=33,$D$35,"") -> 0.55555556 | D16: 0.8
B17: 34 | C17: =IF($I$3=34,$D$35,"") | D17: 0.8
B18: 35 | C18: =IF($I$3=35,$D$35,"") | D18: 0.8
B19: 36 | C19: =IF($I$3=36,$D$35,"") | D19: 0.8
B20: 37 | C20: =IF($I$3=37,$D$35,"") | D20: 0.8
B21: 38 | C21: =IF($I$3=38,$D$35,"") | D21: 0.8
B22: 39 | C22: =IF($I$3=39,$D$35,"") | D22: 0.8 | AJ22: Avance parcial: se repriorizaron los desmontajes de equipos y líneas solicitados por el cliente.
B23: 40 | C23: =IF($I$3=40,$D$35,"") | D23: 0.8
B24: 41 | C24: =IF($I$3=41,$D$35,"") | D24: 0.8
B25: 42 | C25: =IF($I$3=42,$D$35,"") | D25: 0.8
B26: 43 | C26: =IF($I$3=43,$D$35,"") | D26: 0.8
B27: 44 | C27: =IF($I$3=44,$D$35,"") | D27: 0.8
B29: CÁLCULO DE PPC DEL PERIODO
B30: Total de actividades | D30: =D31+D34 -> 9
B31: Actividades programadas | D31: =COUNTIF('PPC '!$O$12:$O$126,"X") -> 9
B32: Actividades ejecutadas programadas | D32: =COUNTIF('PPC '!$AH$11:$AH$126,"SI") -> 5
B33: Actividades no ejecutadas | D33: =D31-D32 -> 4
B34: Actividades ejecutadas no programadas | D34: {=SUMPRODUCT(('PPC '!$O$11:$O$126<>"X")*('PPC '!$AG$11:$AG$126>0)*('PPC '!$D$11:$D$126<>""))} -> 0
B35: % DE CUMPLIMIENTO - PAC | D35: =IFERROR(D32/D31,0) -> 0.55555556
B36: % DE CUMPLIMIENTO - PAE | D36: =IFERROR(D34/D31,0) -> 0
B39: TIPO | C39: DESCRIPCIÓN | D39: 27 | E39: 28 | F39: 29 | G39: 30 | H39: 31 | I39: 32 | J39: 33 | K39: 34 | L39: 35 | M39: 36 | N39: 37 | O39: 38 | P39: 39 | Q39: 40 | R39: 41 | S39: 42 | T39: 43 | U39: 44 | V39: TOTAL
B40: CLI-MAT | C40: CLIENTE - MATERIALES | D40: =IF(D$39='Carátula (P)'!$C$17,COUNTIF('PPC '!$AI$11:$AI$126,$B40),0) -> 0 | E40: =IF(E$39='Carátula (P)'!$C$17,COUNTIF('PPC '!$AI$11:$AI$126,$B40),0) -> 0 | F40: =IF(F$39='Carátula (P)'!$C$17,COUNTIF('PPC '!$AI$11:$AI$126,$B40),0) -> 0 | G40: =IF(G$39='Carátula (P)'!$C$17,COUNTIF('PPC '!$AI$11:$AI$126,$B40),0) -> 0 | H40: =IF(H$39='Carátula (P)'!$C$17,COUNTIF('PPC '!$AI$11:$AI$126,$B40),0) -> 0 | I40: =IF(I$39='Carátula (P)'!$C$17,COUNTIF('PPC '!$AI$11:$AI$126,$B40),0) -> 0 | J40: =IF(J$39='Carátula (P)'!$C$17,COUNTIF('PPC '!$AI$11:$AI$126,$B40),0) -> 0 | K40: =IF(K$39='Carátula (P)'!$C$17,COUNTIF('PPC '!$AI$11:$AI$126,$B40),0) -> 0 | ... U40: =IF(U$39='Carátula (P)'!$C$17,COUNTIF('PPC '!$AI$11:$AI$126,$B40),0) -> 0 | V40: =SUM(D40:U40) -> 0
B41: CLI-ING | C41: CLIENTE - INGENIERÍA | D41: =IF(D$39='Carátula (P)'!$C$17,COUNTIF('PPC '!$AI$11:$AI$126,$B41),0) -> 0 | E41: =IF(E$39='Carátula (P)'!$C$17,COUNTIF('PPC '!$AI$11:$AI$126,$B41),0) -> 0 | F41: =IF(F$39='Carátula (P)'!$C$17,COUNTIF('PPC '!$AI$11:$AI$126,$B41),0) -> 0 | G41: =IF(G$39='Carátula (P)'!$C$17,COUNTIF('PPC '!$AI$11:$AI$126,$B41),0) -> 0 | H41: =IF(H$39='Carátula (P)'!$C$17,COUNTIF('PPC '!$AI$11:$AI$126,$B41),0) -> 0 | I41: =IF(I$39='Carátula (P)'!$C$17,COUNTIF('PPC '!$AI$11:$AI$126,$B41),0) -> 0 | J41: =IF(J$39='Carátula (P)'!$C$17,COUNTIF('PPC '!$AI$11:$AI$126,$B41),0) -> 0 | K41: =IF(K$39='Carátula (P)'!$C$17,COUNTIF('PPC '!$AI$11:$AI$126,$B41),0) -> 0 | ... U41: =IF(U$39='Carátula (P)'!$C$17,COUNTIF('PPC '!$AI$11:$AI$126,$B41),0) -> 0 | V41: =SUM(D41:U41) -> 0
B42: CLI-PRI | C42: CLIENTE - PRIORIDADES | D42: =IF(D$39='Carátula (P)'!$C$17,COUNTIF('PPC '!$AI$11:$AI$126,$B42),0) -> 0 | E42: =IF(E$39='Carátula (P)'!$C$17,COUNTIF('PPC '!$AI$11:$AI$126,$B42),0) -> 0 | F42: =IF(F$39='Carátula (P)'!$C$17,COUNTIF('PPC '!$AI$11:$AI$126,$B42),0) -> 0 | G42: =IF(G$39='Carátula (P)'!$C$17,COUNTIF('PPC '!$AI$11:$AI$126,$B42),0) -> 0 | H42: =IF(H$39='Carátula (P)'!$C$17,COUNTIF('PPC '!$AI$11:$AI$126,$B42),0) -> 0 | I42: =IF(I$39='Carátula (P)'!$C$17,COUNTIF('PPC '!$AI$11:$AI$126,$B42),0) -> 0 | J42: =IF(J$39='Carátula (P)'!$C$17,COUNTIF('PPC '!$AI$11:$AI$126,$B42),0) -> 0 | K42: =IF(K$39='Carátula (P)'!$C$17,COUNTIF('PPC '!$AI$11:$AI$126,$B42),0) -> 0 | ... U42: =IF(U$39='Carátula (P)'!$C$17,COUNTIF('PPC '!$AI$11:$AI$126,$B42),0) -> 0 | V42: =SUM(D42:U42) -> 0
B43: CLI-CAM | C43: CLIENTE - CAMBIO | D43: =IF(D$39='Carátula (P)'!$C$17,COUNTIF('PPC '!$AI$11:$AI$126,$B43),0) -> 0 | E43: =IF(E$39='Carátula (P)'!$C$17,COUNTIF('PPC '!$AI$11:$AI$126,$B43),0) -> 0 | F43: =IF(F$39='Carátula (P)'!$C$17,COUNTIF('PPC '!$AI$11:$AI$126,$B43),0) -> 0 | G43: =IF(G$39='Carátula (P)'!$C$17,COUNTIF('PPC '!$AI$11:$AI$126,$B43),0) -> 0 | H43: =IF(H$39='Carátula (P)'!$C$17,COUNTIF('PPC '!$AI$11:$AI$126,$B43),0) -> 0 | I43: =IF(I$39='Carátula (P)'!$C$17,COUNTIF('PPC '!$AI$11:$AI$126,$B43),0) -> 0 | J43: =IF(J$39='Carátula (P)'!$C$17,COUNTIF('PPC '!$AI$11:$AI$126,$B43),0) -> 4 | K43: =IF(K$39='Carátula (P)'!$C$17,COUNTIF('PPC '!$AI$11:$AI$126,$B43),0) -> 0 | ... U43: =IF(U$39='Carátula (P)'!$C$17,COUNTIF('PPC '!$AI$11:$AI$126,$B43),0) -> 0 | V43: =SUM(D43:U43) -> 4
B44: MAT | C44: MATERIALES | D44: =IF(D$39='Carátula (P)'!$C$17,COUNTIF('PPC '!$AI$11:$AI$126,$B44),0) -> 0 | E44: =IF(E$39='Carátula (P)'!$C$17,COUNTIF('PPC '!$AI$11:$AI$126,$B44),0) -> 0 | F44: =IF(F$39='Carátula (P)'!$C$17,COUNTIF('PPC '!$AI$11:$AI$126,$B44),0) -> 0 | G44: =IF(G$39='Carátula (P)'!$C$17,COUNTIF('PPC '!$AI$11:$AI$126,$B44),0) -> 0 | H44: =IF(H$39='Carátula (P)'!$C$17,COUNTIF('PPC '!$AI$11:$AI$126,$B44),0) -> 0 | I44: =IF(I$39='Carátula (P)'!$C$17,COUNTIF('PPC '!$AI$11:$AI$126,$B44),0) -> 0 | J44: =IF(J$39='Carátula (P)'!$C$17,COUNTIF('PPC '!$AI$11:$AI$126,$B44),0) -> 0 | K44: =IF(K$39='Carátula (P)'!$C$17,COUNTIF('PPC '!$AI$11:$AI$126,$B44),0) -> 0 | ... U44: =IF(U$39='Carátula (P)'!$C$17,COUNTIF('PPC '!$AI$11:$AI$126,$B44),0) -> 0 | V44: =SUM(D44:U44) -> 0
B45: REC | C45: RECURSOS | D45: =IF(D$39='Carátula (P)'!$C$17,COUNTIF('PPC '!$AI$11:$AI$126,$B45),0) -> 0 | E45: =IF(E$39='Carátula (P)'!$C$17,COUNTIF('PPC '!$AI$11:$AI$126,$B45),0) -> 0 | F45: =IF(F$39='Carátula (P)'!$C$17,COUNTIF('PPC '!$AI$11:$AI$126,$B45),0) -> 0 | G45: =IF(G$39='Carátula (P)'!$C$17,COUNTIF('PPC '!$AI$11:$AI$126,$B45),0) -> 0 | H45: =IF(H$39='Carátula (P)'!$C$17,COUNTIF('PPC '!$AI$11:$AI$126,$B45),0) -> 0 | I45: =IF(I$39='Carátula (P)'!$C$17,COUNTIF('PPC '!$AI$11:$AI$126,$B45),0) -> 0 | J45: =IF(J$39='Carátula (P)'!$C$17,COUNTIF('PPC '!$AI$11:$AI$126,$B45),0) -> 0 | K45: =IF(K$39='Carátula (P)'!$C$17,COUNTIF('PPC '!$AI$11:$AI$126,$B45),0) -> 0 | ... U45: =IF(U$39='Carátula (P)'!$C$17,COUNTIF('PPC '!$AI$11:$AI$126,$B45),0) -> 0 | V45: =SUM(D45:U45) -> 0
B46: EP | C46: ERROR PLANIFICACION | D46: =IF(D$39='Carátula (P)'!$C$17,COUNTIF('PPC '!$AI$11:$AI$126,$B46),0) -> 0 | E46: =IF(E$39='Carátula (P)'!$C$17,COUNTIF('PPC '!$AI$11:$AI$126,$B46),0) -> 0 | F46: =IF(F$39='Carátula (P)'!$C$17,COUNTIF('PPC '!$AI$11:$AI$126,$B46),0) -> 0 | G46: =IF(G$39='Carátula (P)'!$C$17,COUNTIF('PPC '!$AI$11:$AI$126,$B46),0) -> 0 | H46: =IF(H$39='Carátula (P)'!$C$17,COUNTIF('PPC '!$AI$11:$AI$126,$B46),0) -> 0 | I46: =IF(I$39='Carátula (P)'!$C$17,COUNTIF('PPC '!$AI$11:$AI$126,$B46),0) -> 0 | J46: =IF(J$39='Carátula (P)'!$C$17,COUNTIF('PPC '!$AI$11:$AI$126,$B46),0) -> 0 | K46: =IF(K$39='Carátula (P)'!$C$17,COUNTIF('PPC '!$AI$11:$AI$126,$B46),0) -> 0 | ... U46: =IF(U$39='Carátula (P)'!$C$17,COUNTIF('PPC '!$AI$11:$AI$126,$B46),0) -> 0 | V46: =SUM(D46:U46) -> 0
...

Sheet Analisis de Restricciones
F2: “Instalación de Tuberías HDPE – Paquetes 07 y 08 – WTP”
F3: ANÁLISIS DE RESTRICCIONES
F4: GENERAL
G5: PERIODO: | H5: =Carátula!C18 -> 46241 | I5: al | J5: =Carátula!E18 -> 46247
C7: SEMANA : | D7: =Carátula!C17 -> 33 | F7: 2026
B8: Item | C8: Activity ID | D8: Codigo | E8: Actividad | F8: Descripción de la Restricción | G8: Acción necesaria | H8: Fecha de Identificación | I8: Fecha de Liberación Requerida | J8: Fecha Prevista | K8: Nueva fecha | L8: Área responsable de liberación | M8: Personal responsable de liberación | N8: Importancia | O8: Fecha de Liberación programada | P8: Estado de la restricción | Q8: Comentario | R8: Comentario | S8: Comentario
E9: FRENTE: INSTRUMENTACIÓN — SUMINISTRO DE INSTRUMENTOS
B10: 1 | C10: A1770 | D10: 5.05.04 | E10: Cable multipar red DeviceNet (2PR, blindado) | F10: Se solicita el material / instrumento para seguir con los avances programados (S36). | G10: Seguimiento a la compra y entrega en obra antes del inicio de la S36. | H10: 46248 | I10: 46262 | J10: 46255 | L10: CPQ | M10: Logística CPQ | N10: BAJA | O10: =J10 -> 46255 | P10: PENDIENTE | Q10: Se solicita el material / instrumento para seguir con los avances.
B11: 2 | C11: A1790 | D11: 5.05.06 | E11: Tarjetas de comunicación DeviceNet para VFDs existentes | F11: Se solicita el material / instrumento para seguir con los avances programados (S37). | G11: Seguimiento a la compra y entrega en obra antes del inicio de la S37. | H11: 46248 | I11: 46269 | J11: 46262 | L11: CPQ | M11: Logística CPQ | N11: BAJA | O11: =J11 -> 46262 | P11: PENDIENTE | Q11: Se solicita el material / instrumento para seguir con los avances.
B12: 3 | C12: A1560 | D12: 5.03.01 | E12: Manómetros tipo bourdon con sello de diafragma Ø1/2" NPT | F12: Se solicita el material / instrumento para seguir con los avances programados (S39). | G12: Seguimiento a la compra y entrega en obra antes del inicio de la S39. | H12: 46248 | I12: 46283 | J12: 46276 | L12: CPQ | M12: Logística CPQ | N12: BAJA | O12: =J12 -> 46276 | P12: PENDIENTE | Q12: Se solicita el material / instrumento para seguir con los avances.
B13: 4 | C13: A1570 | D13: 5.03.02 | E13: Sensor de flujo electromagnético Ø1" #150 (CS/Tefzel) | F13: Se solicita el material / instrumento para seguir con los avances programados (S40). | G13: Seguimiento a la compra y entrega en obra antes del inicio de la S40. | H13: 46248 | I13: 46290 | J13: 46283 | L13: CPQ | M13: Logística CPQ | N13: BAJA | O13: =J13 -> 46283 | P13: PENDIENTE | Q13: Se solicita el material / instrumento para seguir con los avances.
B14: 5 | C14: A1580 | D14: 5.03.03 | E14: Sensor de flujo electromagnético Ø1/2" #150 (CS/Tefzel) | F14: Se solicita el material / instrumento para seguir con los avances programados (S40). | G14: Seguimiento a la compra y entrega en obra antes del inicio de la S40. | H14: 46248 | I14: 46290 | J14: 46283 | L14: CPQ | M14: Logística CPQ | N14: BAJA | O14: =J14 -> 46283 | P14: PENDIENTE | Q14: Se solicita el material / instrumento para seguir con los avances.
B15: 6 | C15: A1590 | D15: 5.03.04 | E15: Sensor de flujo electromagnético Ø1-1/2" #150 (SS/PTFE) | F15: Se solicita el material / instrumento para seguir con los avances programados (S40). | G15: Seguimiento a la compra y entrega en obra antes del inicio de la S40. | H15: 46248 | I15: 46290 | J15: 46283 | L15: CPQ | M15: Logística CPQ | N15: BAJA | O15: =J15 -> 46283 | P15: PENDIENTE | Q15: Se solicita el material / instrumento para seguir con los avances.
B16: 7 | C16: A1600 | D16: 5.03.05 | E16: Sensor de flujo electromagnético Ø1" #150 (SS/PTFE) | F16: Se solicita el material / instrumento para seguir con los avances programados (S40). | G16: Seguimiento a la compra y entrega en obra antes del inicio de la S40. | H16: 46248 | I16: 46290 | J16: 46283 | L16: CPQ | M16: Logística CPQ | N16: BAJA | O16: =J16 -> 46283 | P16: PENDIENTE | Q16: Se solicita el material / instrumento para seguir con los avances.
B17: 8 | C17: A1620 | D17: 5.03.07 | E17: Sensor/transmisor de nivel radar (antena PVDF, Ø1-1/2") | F17: Se solicita el material / instrumento para seguir con los avances programados (S40). | G17: Seguimiento a la compra y entrega en obra antes del inicio de la S40. | H17: 46248 | I17: 46290 | J17: 46283 | L17: CPQ | M17: Logística CPQ | N17: BAJA | O17: =J17 -> 46283 | P17: PENDIENTE | Q17: Se solicita el material / instrumento para seguir con los avances.
B18: 9 | C18: A1610 | D18: 5.03.06 | E18: Transmisores indicadores de flujo digitales (4-20mA+HART) | F18: Se solicita el material / instrumento para seguir con los avances programados (S41). | G18: Seguimiento a la compra y entrega en obra antes del inicio de la S41. | H18: 46248 | I18: 46297 | J18: 46290 | L18: CPQ | M18: Logística CPQ | N18: BAJA | O18: =J18 -> 46290 | P18: PENDIENTE | Q18: Se solicita el material / instrumento para seguir con los avances.
B19: 10 | C19: A1630 | D19: 5.03.08 | E19: Indicador de nivel digital programable | F19: Se solicita el material / instrumento para seguir con los avances programados (S41). | G19: Seguimiento a la compra y entrega en obra antes del inicio de la S41. | H19: 46248 | I19: 46297 | J19: 46290 | L19: CPQ | M19: Logística CPQ | N19: BAJA | O19: =J19 -> 46290 | P19: PENDIENTE | Q19: Se solicita el material / instrumento para seguir con los avances.
B20: 11 | C20: A1700 | D20: 5.04.01 | E20: Válvula de control tipo globo Ø2" #150 c/actuador y posicionador | F20: Se solicita el material / instrumento para seguir con los avances programados (S41). | G20: Seguimiento a la compra y entrega en obra antes del inicio de la S41. | H20: 46248 | I20: 46297 | J20: 46290 | L20: CPQ | M20: Logística CPQ | N20: BAJA | O20: =J20 -> 46290 | P20: PENDIENTE | Q20: Se solicita el material / instrumento para seguir con los avances.
B21: 12 | C21: A1710 | D21: 5.04.02 | E21: Válvula de control tipo globo Ø1-1/2" #150 c/actuador y posicionador | F21: Se solicita el material / instrumento para seguir con los avances programados (S41). | G21: Seguimiento a la compra y entrega en obra antes del inicio de la S41. | H21: 46248 | I21: 46297 | J21: 46290 | L21: CPQ | M21: Logística CPQ | N21: BAJA | O21: =J21 -> 46290 | P21: PENDIENTE | Q21: Se solicita el material / instrumento para seguir con los avances.
E22: FRENTE: MECÁNICA — SUMINISTROS Y LIBERACIONES DE MINA (MY)
B23: 13 | C23: A1340 | D23: 3.06.01 | E23: Tubería y accesorios 3" AA1B — materiales entregados por MY | F23: Se solicita el material a MY para seguir con los avances programados (S34). | G23: Coordinar con MY la entrega / liberación antes del inicio de la S34. | H23: 46248 | I23: 46248 | J23: 46241 | L23: MY | M23: Almacén / Operaciones MY | N23: BAJA | O23: 46241 | P23: PENDIENTE | Q23: Se solicita el material a MY para seguir con los avances.
B24: 14 | C24: A1350 | D24: 3.06.02 | E24: Tubería y accesorios 4" AA1B — materiales entregados por MY | F24: Se solicita el material a MY para seguir con los avances programados (S37). | G24: Coordinar con MY la entrega / liberación antes del inicio de la S37. | H24: 46248 | I24: 46269 | J24: 46262 | L24: MY | M24: Almacén / Operaciones MY | N24: BAJA | O24: 46262 | P24: PENDIENTE | Q24: Se solicita el material a MY para seguir con los avances.
B25: 15 | C25: A1270 | D25: 3.04 | E25: Bombas de dosificación de floculante (5 und) — equipo entregado por MY | F25: Se solicita el material a MY para seguir con los avances programados (S36). | G25: Coordinar con MY la entrega / liberación antes del inicio de la S36. | H25: 46248 | I25: 46262 | J25: 46255 | L25: MY | M25: Almacén / Operaciones MY | N25: BAJA | O25: 46255 | P25: PENDIENTE | Q25: Se solicita el material a MY para seguir con los avances.
B26: 16 | C26: A1320 | D26: 3.05 | E26: Bombas para agua de dilución (2 und) — equipo entregado por MY | F26: Se solicita el material a MY para seguir con los avances programados (S43). | G26: Coordinar con MY la entrega / liberación antes del inicio de la S43. | H26: 46248 | I26: 46311 | J26: 46304 | L26: MY | M26: Almacén / Operaciones MY | N26: BAJA | O26: 46304 | P26: PENDIENTE | Q26: Se solicita el material a MY para seguir con los avances.
B27: 17 | C27: A1400 | D27: 3.07 | E27: Tie-ins M-001/M-002 — liberación de línea por MY | F27: Se solicita el material a MY para seguir con los avances programados (S40). | G27: Coordinar con MY la entrega / liberación antes del inicio de la S40. | H27: 46248 | I27: 46290 | J27: 46283 | L27: MY | M27: Almacén / Operaciones MY | N27: BAJA | O27: 46283 | P27: PENDIENTE | Q27: Se solicita el material a MY para seguir con los avances.
B29: LEYENDA
B30: Importancia: | C30: ALTA | D30: MEDIA | E30: BAJA
B31: Estado: | C31: PENDIENTE | D31: LIBERADA
