Workbook

Sheet PANEL CONTROL
AC15: CONSTRUCTION PROGRESS : | AG15: ='Carátula (P)'!C17 -> 34
AF16: SEMANAL | AJ16: ACUMULADO
AF17: Planned | AH17: Actual | AJ17: Planned | AL17: Actual
AC18: LB0 | AF18: =IFERROR(INDEX('PHYSICAL % PROGRESS'!P220:AG220,MATCH($AG$15,'PHYSICAL % PROGRESS'!$P$7:$AG$7,0)),0) -> 0.0705352 | AH18: =IFERROR(INDEX('PHYSICAL % PROGRESS'!P221:AG221,MATCH($AG$15,'PHYSICAL % PROGRESS'!$P$7:$AG$7,0)),0) -> 0.009062 | AJ18: =IFERROR(INDEX('PHYSICAL % PROGRESS'!P218:AG218,MATCH($AG$15,'PHYSICAL % PROGRESS'!$P$7:$AG$7,0)),0) -> 0.14453844 | AL18: =IFERROR(INDEX('PHYSICAL % PROGRESS'!P219:AG219,MATCH($AG$15,'PHYSICAL % PROGRESS'!$P$7:$AG$7,0)),0) -> 0.050218
AC19: ReProg
AC20: RESPECTO AL CRONOGRAMA LB0
AC21: SPI (Semanal | AF21: =IFERROR(AH18/AF18,0) -> 0.12847486 | AI21: SPI (Total) | AL21: =IFERROR(AL18/AJ18,0) -> 0.34743699
AC23: Estatus RFI's
AC24: Enviados | AG24: =COUNT(RFI!$B$9:$B$200) -> 2 | AH24: Pendiente p/MY | AJ24: =COUNTIF(RFI!$C$9:$C$200,"ABIERTO") -> 0 | AK24: No completado | AM24: =COUNTIF(RFI!$J$9:$J$200,"NO COMPLETADO") -> 0
AC25: Respondidos por MY | AG25: =COUNT(RFI!$L$9:$L$200) -> 2 | AH25: Cancelado | AJ25: =COUNTIF(RFI!$J$9:$J$200,"ANULADO") -> 0 | AK25: Cerrado | AM25: =COUNTIF(RFI!$C$9:$C$200,"CERRADO") -> 2
AC26: Estatus FCR's
AC27: Enviados | AG27: =COUNT(FCR!$A$9:$A$200) -> 2 | AH27: Pendiente p/MY | AJ27: =COUNTIF(FCR!$J$9:$J$200,"PENDIENTE*") -> 0 | AK27: No completado | AM27: =COUNTIF(FCR!$J$9:$J$200,"NO COMPLETADO") -> 0
AC28: Respondidos por MY | AG28: =COUNT(FCR!$I$9:$I$200) -> 2 | AH28: Cancelado | AJ28: =COUNTIF(FCR!$J$9:$J$200,"ANULADO") -> 0 | AK28: Cerrado | AM28: =COUNTIF(FCR!$J$9:$J$200,"PROCEDE*")+COUNTIF(FCR!$J$9:$J$200,"CERRADO*") -> 2
AC29: Estatus Protocolos QA/QC
AC30: Presentados | AG30: 0 | AH30: Pendiente p/MY | AJ30: 0
AC31: Aprobados Por MY | AG31: 0 | AH31: Observado p/MY | AJ31: 0
AC32: RESPECTO AL CRONOGRAMA LB0
AC33: COSTOS USD: | AF33: SEMANA | AJ33: ACUMULADO
AF34: Planned | AH34: Actual | AJ34: Planned | AL34: Actual
AC35: Contrato Original | AF35: =IFERROR(INDEX(COSTO!H216:Y216,MATCH($AG$15,COSTO!$H$3:$Y$3,0)),0) -> 10638.032 | AH35: =IFERROR(INDEX(COSTO!H217:Y217,MATCH($AG$15,COSTO!$H$3:$Y$3,0)),0) -> 1389.9606 | AJ35: =IFERROR(INDEX(COSTO!H214:Y214,MATCH($AG$15,COSTO!$H$3:$Y$3,0)),0) -> 21264.279 | AL35: =IFERROR(INDEX(COSTO!H215:Y215,MATCH($AG$15,COSTO!$H$3:$Y$3,0)),0) -> 6924.5933
AC37: CPI (Semanal) | AF37: =IFERROR(AH35/AF35,0) -> 0.13065956 | AI37: CPI (Total) | AL37: =IFERROR(AL35/AJ35,0) -> 0.3256444
AC39: CUMPLIMIENTOS Y OBSERVACIONES
AC40: Desmontaje de válvulas de control (FCV-1715334/338/342) y de sensores/transmisores de flujo (FE/FIT); desmontaje de líneas inoperativas de 1"–1½" y de bomba 1760-PU-33104; demolición de 2 bases de concreto (0.38 de 1.28 m3) y retiro de bases de bombas; traslado de andamios de Cajamarca a Pampa Larga. Trazo y replanteo 60%, limpieza del área 50%. Se retiro varias partidas de la diciplina electrica, formalmente mediante un correo. Se tiene la indicación de reducir mas alcance, se emitió un correo respecto al tema, el cual sera tratado el dia lunes 17/08/2026. El actual reporte ya no considera las partidas retiradas, asi mismo , se informa que para proceder a los trabajos, es necesario realizar la actividad de Desmontaje y Montaje de la linea de 3" con un rendimiento reducido a la mitad, mismo cambio que ya es reflejado en el actual reporte.
AC50: PROBLEMAS/RESTRICCIONES
AC51: Alerta roja por tormenta eléctrica el 12-ago (10:02–10:08) detuvo los trabajos en campo; camión grúa disponible solo 0.4 de turno (4 h) para los desmontajes.
AC58: RIESGOS / OPORTUNIDADES
AC59: Tormentas eléctricas recurrentes en la zona pueden reducir el rendimiento de los trabajos a la intemperie (demolición, desmontajes e izajes).
AC70: PLAN DE MITIGACIÓN
AC71: Programar izajes y vaciados en ventanas de la mañana; aplicar refugio y pausas por alerta roja según estándar MY; asegurar disponibilidad del camión grúa para los desmontajes de la próxima semana.
B73: ESTADÍSTICAS DE RESPONSABILIDAD SOCIAL
AC84: CONTRATO: | AD84: CW156993 — WO003
AC85: CONTRATISTA: | AE85: CONSORCIO CPQ COLUMBITO
AC86: PROYECTO: | AE86: =PROGRAMACION!D5 -> REPOSICION DEL SISTEMA DE FLOCULANTES — LB0
AC87: ACTUALIZACIÓN: | AE87: ='Carátula (P)'!C17 -> 34
C91: PERSONAL REAL
C92: VARONES | F92: =IFERROR(E92/E94,0) -> 0 | G92: CAJAMARQUINOS | J92: =IFERROR(I92/I94,0) -> 0 | K92: COMUNIDAD | N92: =IFERROR(M92/M94,0) -> 0
C93: MUJERES | F93: =IFERROR(E93/E94,0) -> 0 | G93: FORANEOS | J93: =IFERROR(I93/I94,0) -> 0 | K93: NO COMUNIDAD | N93: =IFERROR(M93/M94,0) -> 0
E94: =SUM(E92:E93) -> 0 | F94: =SUM(F92:F93) -> 0 | I94: =SUM(I92:I93) -> 0 | J94: =SUM(J92:J93) -> 0 | M94: =SUM(M92:M93) -> 0 | N94: =SUM(N92:N93) -> 0

Sheet STAFFING TABULATION CHART
B2: STAFFING TABULATION CHART
B4: Contract No: | C4: ='PHYSICAL % PROGRESS'!F1 -> 0
B5: Contractor Name: | C5: ='PHYSICAL % PROGRESS'!F2 -> CONSORCIO CPQ COLUMBITO
B6: Description: | C6: ='PHYSICAL % PROGRESS'!F3 -> REPOSICION DEL SISTEMA DE FLOCULANTES — LB0
D9: ='PHYSICAL % PROGRESS'!P7 -> 27 | E9: ='PHYSICAL % PROGRESS'!Q7 -> 28 | F9: ='PHYSICAL % PROGRESS'!R7 -> 29 | G9: ='PHYSICAL % PROGRESS'!S7 -> 30 | H9: ='PHYSICAL % PROGRESS'!T7 -> 31 | I9: ='PHYSICAL % PROGRESS'!U7 -> 32 | J9: ='PHYSICAL % PROGRESS'!V7 -> 33 | K9: ='PHYSICAL % PROGRESS'!W7 -> 34 | ... U9: ='PHYSICAL % PROGRESS'!AG7 -> 44
D10: ='PHYSICAL % PROGRESS'!P8 -> 46199 | E10: ='PHYSICAL % PROGRESS'!Q8 -> 46206 | F10: ='PHYSICAL % PROGRESS'!R8 -> 46213 | G10: ='PHYSICAL % PROGRESS'!S8 -> 46220 | H10: ='PHYSICAL % PROGRESS'!T8 -> 46227 | I10: ='PHYSICAL % PROGRESS'!U8 -> 46234 | J10: ='PHYSICAL % PROGRESS'!V8 -> 46241 | K10: ='PHYSICAL % PROGRESS'!W8 -> 46248 | ... U10: ='PHYSICAL % PROGRESS'!AG8 -> 46318
D11: ='PHYSICAL % PROGRESS'!P9 -> 46205 | E11: ='PHYSICAL % PROGRESS'!Q9 -> 46212 | F11: ='PHYSICAL % PROGRESS'!R9 -> 46219 | G11: ='PHYSICAL % PROGRESS'!S9 -> 46226 | H11: ='PHYSICAL % PROGRESS'!T9 -> 46233 | I11: ='PHYSICAL % PROGRESS'!U9 -> 46240 | J11: ='PHYSICAL % PROGRESS'!V9 -> 46247 | K11: ='PHYSICAL % PROGRESS'!W9 -> 46254 | ... U11: ='PHYSICAL % PROGRESS'!AG9 -> 46324
B12: STAFF
B13: Residente de Obra | C13: Plan | D13: 1 | E13: 1 | F13: 1 | G13: 1 | H13: 1 | I13: 1 | J13: 1 | K13: 1 | L13: 1 | M13: 1 | N13: 1 | O13: 1 | P13: 1 | Q13: 1 | R13: 1 | S13: 1 | T13: 1 | U13: 1
C14: Act. | G14: 1 | H14: 1 | I14: 1 | J14: 1
B15: Ingeniero Supervisor | C15: Plan | D15: 2 | E15: 2 | F15: 2 | G15: 2 | H15: 2 | I15: 2 | J15: 2 | K15: 2 | L15: 2 | M15: 2 | N15: 2 | O15: 2 | P15: 2 | Q15: 2 | R15: 2 | S15: 2 | T15: 2 | U15: 2
C16: Act. | G16: 3 | H16: 3 | I16: 3 | J16: 3
B17: Ingeniero de Control de Proyectos | C17: Plan | D17: 1 | E17: 1 | F17: 1 | G17: 1 | H17: 1 | I17: 1 | J17: 1 | K17: 1 | L17: 1 | M17: 1 | N17: 1 | O17: 1 | P17: 1 | Q17: 1 | R17: 1 | S17: 1 | T17: 1 | U17: 1
C18: Act. | G18: 1 | H18: 1 | I18: 1 | J18: 1
B19: Ingeniero de Calidad | C19: Plan | D19: 1 | E19: 1 | F19: 1 | G19: 1 | H19: 1 | I19: 1 | J19: 1 | K19: 1 | L19: 1 | M19: 1 | N19: 1 | O19: 1 | P19: 1 | Q19: 1 | R19: 1 | S19: 1 | T19: 1 | U19: 1
C20: Act. | G20: 1 | H20: 1 | I20: 1 | J20: 1
B21: Administrador de Obra | C21: Plan | D21: 1 | E21: 1 | F21: 1 | G21: 1 | H21: 1 | I21: 1 | J21: 1 | K21: 1 | L21: 1 | M21: 1 | N21: 1 | O21: 1 | P21: 1 | Q21: 1 | R21: 1 | S21: 1 | T21: 1 | U21: 1
C22: Act. | G22: 1 | H22: 1 | I22: 1 | J22: 1
B23: Topógrafo | C23: Plan | D23: 1 | E23: 1 | F23: 1 | G23: 1 | H23: 1 | I23: 1 | J23: 1 | K23: 1 | L23: 1 | M23: 1 | N23: 1 | O23: 1 | P23: 1 | Q23: 1 | R23: 1 | S23: 1 | T23: 1 | U23: 1
C24: Act. | G24: 1 | H24: 1 | I24: 1 | J24: 1
B26: TOTAL STAFF | C26: Plan | D26: =SUM(D13,D15,D17,D19,D21,D23) -> 7 | E26: =SUM(E13,E15,E17,E19,E21,E23) -> 7 | F26: =SUM(F13,F15,F17,F19,F21,F23) -> 7 | G26: =SUM(G13,G15,G17,G19,G21,G23) -> 7 | H26: =SUM(H13,H15,H17,H19,H21,H23) -> 7 | I26: =SUM(I13,I15,I17,I19,I21,I23) -> 7 | J26: =SUM(J13,J15,J17,J19,J21,J23) -> 7 | K26: =SUM(K13,K15,K17,K19,K21,K23) -> 7 | ... U26: =SUM(U13,U15,U17,U19,U21,U23) -> 7
C27: Act. | D27: =SUM(D14,D16,D18,D20,D22,D24) -> 0 | E27: =SUM(E14,E16,E18,E20,E22,E24) -> 0 | F27: =SUM(F14,F16,F18,F20,F22,F24) -> 0 | G27: =SUM(G14,G16,G18,G20,G22,G24) -> 8 | H27: =SUM(H14,H16,H18,H20,H22,H24) -> 8 | I27: =SUM(I14,I16,I18,I20,I22,I24) -> 8 | J27: =SUM(J14,J16,J18,J20,J22,J24) -> 8 | K27: =SUM(K14,K16,K18,K20,K22,K24) -> 0 | ... U27: =SUM(U14,U16,U18,U20,U22,U24) -> 0
B30: PERSONAL INDIRECTO
B31: Conductor (COUSTER, CAMIONETA) | C31: Plan | D31: 5 | E31: 5 | F31: 5 | G31: 5 | H31: 5 | I31: 5 | J31: 5 | K31: 5 | L31: 5 | M31: 5 | N31: 5 | O31: 5 | P31: 5 | Q31: 5 | R31: 5 | S31: 5 | T31: 5 | U31: 5
C32: Act. | G32: 2 | H32: 2 | I32: 2 | J32: 2
B33: Operador camión grúa | C33: Plan | D33: 1 | E33: 1 | F33: 1 | G33: 1 | H33: 1 | I33: 1 | J33: 1 | K33: 1 | L33: 1 | M33: 1 | N33: 1 | O33: 1 | P33: 1 | Q33: 1 | R33: 1 | S33: 1 | T33: 1 | U33: 1
C34: Act. | G34: 1 | H34: 1 | I34: 1 | J34: 1
B35: Operador camión 4tn | C35: Plan | D35: 1 | E35: 1 | F35: 1 | G35: 1 | H35: 1 | I35: 1 | J35: 1 | K35: 1 | L35: 1 | M35: 1 | N35: 1 | O35: 1 | P35: 1 | Q35: 1 | R35: 1 | S35: 1 | T35: 1 | U35: 1
C36: Act.
B37: Rigger | C37: Plan | D37: 1 | E37: 1 | F37: 1 | G37: 1 | H37: 1 | I37: 1 | J37: 1 | K37: 1 | L37: 1 | M37: 1 | N37: 1 | O37: 1 | P37: 1 | Q37: 1 | R37: 1 | S37: 1 | T37: 1 | U37: 1
C38: Act. | G38: 1 | H38: 1 | I38: 1 | J38: 1
B39: Almacenero | C39: Plan | D39: 1 | E39: 1 | F39: 1 | G39: 1 | H39: 1 | I39: 1 | J39: 1 | K39: 1 | L39: 1 | M39: 1 | N39: 1 | O39: 1 | P39: 1 | Q39: 1 | R39: 1 | S39: 1 | T39: 1 | U39: 1
C40: Act. | G40: 1 | H40: 1 | I40: 1 | J40: 1
B42: TOTAL | C42: Plan | D42: =SUM(D31,D33,D35,D37,D39) -> 9 | E42: =SUM(E31,E33,E35,E37,E39) -> 9 | F42: =SUM(F31,F33,F35,F37,F39) -> 9 | G42: =SUM(G31,G33,G35,G37,G39) -> 9 | H42: =SUM(H31,H33,H35,H37,H39) -> 9 | I42: =SUM(I31,I33,I35,I37,I39) -> 9 | J42: =SUM(J31,J33,J35,J37,J39) -> 9 | K42: =SUM(K31,K33,K35,K37,K39) -> 9 | ... U42: =SUM(U31,U33,U35,U37,U39) -> 9
C43: Act. | D43: =SUM(D32,D34,D36,D38,D40) -> 0 | E43: =SUM(E32,E34,E36,E38,E40) -> 0 | F43: =SUM(F32,F34,F36,F38,F40) -> 0 | G43: =SUM(G32,G34,G36,G38,G40) -> 5 | H43: =SUM(H32,H34,H36,H38,H40) -> 5 | I43: =SUM(I32,I34,I36,I38,I40) -> 5 | J43: =SUM(J32,J34,J36,J38,J40) -> 5 | K43: =SUM(K32,K34,K36,K38,K40) -> 0 | ... U43: =SUM(U32,U34,U36,U38,U40) -> 0
B46: LABOR
B47: ='Para Histograma'!D577&" ("&'Para Histograma'!E577&")" -> CAPATAZ (CIVIL) | C47: Plan | D47: ='Para Histograma'!L577 -> 0 | E47: ='Para Histograma'!M577 -> 0 | F47: ='Para Histograma'!N577 -> 0 | G47: ='Para Histograma'!O577 -> 1 | H47: ='Para Histograma'!P577 -> 1 | I47: ='Para Histograma'!Q577 -> 1 | J47: ='Para Histograma'!R577 -> 1 | K47: ='Para Histograma'!S577 -> 0 | ... U47: ='Para Histograma'!AC577 -> 0
C48: Act. | G48: 1 | H48: 1 | I48: 1 | J48: 1
B49: ='Para Histograma'!D578&" ("&'Para Histograma'!E578&")" -> AYUDANTE (CIVIL) | C49: Plan | D49: ='Para Histograma'!L578 -> 0 | E49: ='Para Histograma'!M578 -> 0 | F49: ='Para Histograma'!N578 -> 0 | G49: ='Para Histograma'!O578 -> 2 | H49: ='Para Histograma'!P578 -> 2 | I49: ='Para Histograma'!Q578 -> 2 | J49: ='Para Histograma'!R578 -> 2 | K49: ='Para Histograma'!S578 -> 1 | ... U49: ='Para Histograma'!AC578 -> 0
C50: Act. | H50: 1 | I50: 1 | J50: 1
...

Sheet CONSTRUCTION EQUIPMENT SCHE 
B2: CONSTRUCTION EQUIPMENT SCHEDULE
B4: Contract No: | C4: ='STAFFING TABULATION CHART'!C4 -> 0
B5: Contractor Name: | C5: ='STAFFING TABULATION CHART'!C5 -> CONSORCIO CPQ COLUMBITO
B6: Description: | C6: ='STAFFING TABULATION CHART'!C6 -> REPOSICION DEL SISTEMA DE FLOCULANTES — LB0
D9: ='PHYSICAL % PROGRESS'!P7 -> 27 | E9: ='PHYSICAL % PROGRESS'!Q7 -> 28 | F9: ='PHYSICAL % PROGRESS'!R7 -> 29 | G9: ='PHYSICAL % PROGRESS'!S7 -> 30 | H9: ='PHYSICAL % PROGRESS'!T7 -> 31 | I9: ='PHYSICAL % PROGRESS'!U7 -> 32 | J9: ='PHYSICAL % PROGRESS'!V7 -> 33 | K9: ='PHYSICAL % PROGRESS'!W7 -> 34 | ... U9: ='PHYSICAL % PROGRESS'!AG7 -> 44
D10: ='PHYSICAL % PROGRESS'!P8 -> 46199 | E10: ='PHYSICAL % PROGRESS'!Q8 -> 46206 | F10: ='PHYSICAL % PROGRESS'!R8 -> 46213 | G10: ='PHYSICAL % PROGRESS'!S8 -> 46220 | H10: ='PHYSICAL % PROGRESS'!T8 -> 46227 | I10: ='PHYSICAL % PROGRESS'!U8 -> 46234 | J10: ='PHYSICAL % PROGRESS'!V8 -> 46241 | K10: ='PHYSICAL % PROGRESS'!W8 -> 46248 | ... U10: ='PHYSICAL % PROGRESS'!AG8 -> 46318
D11: ='PHYSICAL % PROGRESS'!P9 -> 46205 | E11: ='PHYSICAL % PROGRESS'!Q9 -> 46212 | F11: ='PHYSICAL % PROGRESS'!R9 -> 46219 | G11: ='PHYSICAL % PROGRESS'!S9 -> 46226 | H11: ='PHYSICAL % PROGRESS'!T9 -> 46233 | I11: ='PHYSICAL % PROGRESS'!U9 -> 46240 | J11: ='PHYSICAL % PROGRESS'!V9 -> 46247 | K11: ='PHYSICAL % PROGRESS'!W9 -> 46254 | ... U11: ='PHYSICAL % PROGRESS'!AG9 -> 46324
B12: DESCRIPTION
B13: ='Para Histograma'!D599 -> CAMION GRUA DE 12TN | C13: Plan | D13: ='Para Histograma'!L599 -> 0 | E13: ='Para Histograma'!M599 -> 0 | F13: ='Para Histograma'!N599 -> 0 | G13: ='Para Histograma'!O599 -> 1 | H13: ='Para Histograma'!P599 -> 0 | I13: ='Para Histograma'!Q599 -> 0 | J13: ='Para Histograma'!R599 -> 0 | K13: ='Para Histograma'!S599 -> 0 | ... U13: ='Para Histograma'!AC599 -> 0
C14: Act.
B15: ='Para Histograma'!D600 -> CAMION BARANDA (4TN) | C15: Plan | D15: ='Para Histograma'!L600 -> 0 | E15: ='Para Histograma'!M600 -> 0 | F15: ='Para Histograma'!N600 -> 0 | G15: ='Para Histograma'!O600 -> 1 | H15: ='Para Histograma'!P600 -> 0 | I15: ='Para Histograma'!Q600 -> 0 | J15: ='Para Histograma'!R600 -> 0 | K15: ='Para Histograma'!S600 -> 0 | ... U15: ='Para Histograma'!AC600 -> 0
C16: Act.
B17: ='Para Histograma'!D601 -> NIVEL DE INGENIERO | C17: Plan | D17: ='Para Histograma'!L601 -> 0 | E17: ='Para Histograma'!M601 -> 0 | F17: ='Para Histograma'!N601 -> 0 | G17: ='Para Histograma'!O601 -> 0 | H17: ='Para Histograma'!P601 -> 1 | I17: ='Para Histograma'!Q601 -> 0 | J17: ='Para Histograma'!R601 -> 0 | K17: ='Para Histograma'!S601 -> 0 | ... U17: ='Para Histograma'!AC601 -> 0
C18: Act.
B19: ='Para Histograma'!D602 -> ROTOMARTILLO | C19: Plan | D19: ='Para Histograma'!L602 -> 0 | E19: ='Para Histograma'!M602 -> 0 | F19: ='Para Histograma'!N602 -> 0 | G19: ='Para Histograma'!O602 -> 0 | H19: ='Para Histograma'!P602 -> 1 | I19: ='Para Histograma'!Q602 -> 0 | J19: ='Para Histograma'!R602 -> 0 | K19: ='Para Histograma'!S602 -> 0 | ... U19: ='Para Histograma'!AC602 -> 0
C20: Act.
B21: ='Para Histograma'!D603 -> VIBRADORA DE CONCRETO | C21: Plan | D21: ='Para Histograma'!L603 -> 0 | E21: ='Para Histograma'!M603 -> 0 | F21: ='Para Histograma'!N603 -> 0 | G21: ='Para Histograma'!O603 -> 0 | H21: ='Para Histograma'!P603 -> 0 | I21: ='Para Histograma'!Q603 -> 1 | J21: ='Para Histograma'!R603 -> 0 | K21: ='Para Histograma'!S603 -> 0 | ... U21: ='Para Histograma'!AC603 -> 0
C22: Act.
B23: ='Para Histograma'!D604 -> SIERRA CIRCULAR | C23: Plan | D23: ='Para Histograma'!L604 -> 0 | E23: ='Para Histograma'!M604 -> 0 | F23: ='Para Histograma'!N604 -> 0 | G23: ='Para Histograma'!O604 -> 0 | H23: ='Para Histograma'!P604 -> 0 | I23: ='Para Histograma'!Q604 -> 0 | J23: ='Para Histograma'!R604 -> 1 | K23: ='Para Histograma'!S604 -> 0 | ... U23: ='Para Histograma'!AC604 -> 0
C24: Act.
B25: ='Para Histograma'!D605 -> ESMERIL ELÉCTRICO | C25: Plan | D25: ='Para Histograma'!L605 -> 0 | E25: ='Para Histograma'!M605 -> 0 | F25: ='Para Histograma'!N605 -> 0 | G25: ='Para Histograma'!O605 -> 0 | H25: ='Para Histograma'!P605 -> 0 | I25: ='Para Histograma'!Q605 -> 0 | J25: ='Para Histograma'!R605 -> 1 | K25: ='Para Histograma'!S605 -> 0 | ... U25: ='Para Histograma'!AC605 -> 0
C26: Act.
B27: ='Para Histograma'!D606 -> AMOLADORA | C27: Plan | D27: ='Para Histograma'!L606 -> 0 | E27: ='Para Histograma'!M606 -> 0 | F27: ='Para Histograma'!N606 -> 0 | G27: ='Para Histograma'!O606 -> 0 | H27: ='Para Histograma'!P606 -> 0 | I27: ='Para Histograma'!Q606 -> 1 | J27: ='Para Histograma'!R606 -> 1 | K27: ='Para Histograma'!S606 -> 1 | ... U27: ='Para Histograma'!AC606 -> 0
C28: Act.
B29: ='Para Histograma'!D607 -> COMPRESORA | C29: Plan | D29: ='Para Histograma'!L607 -> 0 | E29: ='Para Histograma'!M607 -> 0 | F29: ='Para Histograma'!N607 -> 0 | G29: ='Para Histograma'!O607 -> 0 | H29: ='Para Histograma'!P607 -> 0 | I29: ='Para Histograma'!Q607 -> 0 | J29: ='Para Histograma'!R607 -> 0 | K29: ='Para Histograma'!S607 -> 0 | ... U29: ='Para Histograma'!AC607 -> 0
C30: Act.
B31: ='Para Histograma'!D608 -> MAQUINA DE SOLDAR | C31: Plan | D31: ='Para Histograma'!L608 -> 0 | E31: ='Para Histograma'!M608 -> 0 | F31: ='Para Histograma'!N608 -> 0 | G31: ='Para Histograma'!O608 -> 0 | H31: ='Para Histograma'!P608 -> 0 | I31: ='Para Histograma'!Q608 -> 0 | J31: ='Para Histograma'!R608 -> 0 | K31: ='Para Histograma'!S608 -> 2 | ... U31: ='Para Histograma'!AC608 -> 0
C32: Act.
B33: ='Para Histograma'!D609 -> BATIDORA DE GROUT | C33: Plan | D33: ='Para Histograma'!L609 -> 0 | E33: ='Para Histograma'!M609 -> 0 | F33: ='Para Histograma'!N609 -> 0 | G33: ='Para Histograma'!O609 -> 0 | H33: ='Para Histograma'!P609 -> 0 | I33: ='Para Histograma'!Q609 -> 0 | J33: ='Para Histograma'!R609 -> 0 | K33: ='Para Histograma'!S609 -> 0 | ... U33: ='Para Histograma'!AC609 -> 0
C34: Act.
B35: ='Para Histograma'!D610 -> TERMOHIGÓMETRO | C35: Plan | D35: ='Para Histograma'!L610 -> 0 | E35: ='Para Histograma'!M610 -> 0 | F35: ='Para Histograma'!N610 -> 0 | G35: ='Para Histograma'!O610 -> 0 | H35: ='Para Histograma'!P610 -> 0 | I35: ='Para Histograma'!Q610 -> 0 | J35: ='Para Histograma'!R610 -> 0 | K35: ='Para Histograma'!S610 -> 0 | ... U35: ='Para Histograma'!AC610 -> 0
C36: Act.
B37: ='Para Histograma'!D611 -> PIRÓMETRO | C37: Plan | D37: ='Para Histograma'!L611 -> 0 | E37: ='Para Histograma'!M611 -> 0 | F37: ='Para Histograma'!N611 -> 0 | G37: ='Para Histograma'!O611 -> 0 | H37: ='Para Histograma'!P611 -> 0 | I37: ='Para Histograma'!Q611 -> 0 | J37: ='Para Histograma'!R611 -> 0 | K37: ='Para Histograma'!S611 -> 0 | ... U37: ='Para Histograma'!AC611 -> 0
C38: Act.
B39: ='Para Histograma'!D612 -> TALADRO PERCUTOR | C39: Plan | D39: ='Para Histograma'!L612 -> 0 | E39: ='Para Histograma'!M612 -> 0 | F39: ='Para Histograma'!N612 -> 0 | G39: ='Para Histograma'!O612 -> 0 | H39: ='Para Histograma'!P612 -> 0 | I39: ='Para Histograma'!Q612 -> 0 | J39: ='Para Histograma'!R612 -> 1 | K39: ='Para Histograma'!S612 -> 1 | ... U39: ='Para Histograma'!AC612 -> 0
C40: Act.
B41: ='Para Histograma'!D613 -> MOTOBOMBA | C41: Plan | D41: ='Para Histograma'!L613 -> 0 | E41: ='Para Histograma'!M613 -> 0 | F41: ='Para Histograma'!N613 -> 0 | G41: ='Para Histograma'!O613 -> 0 | H41: ='Para Histograma'!P613 -> 0 | I41: ='Para Histograma'!Q613 -> 0 | J41: ='Para Histograma'!R613 -> 0 | K41: ='Para Histograma'!S613 -> 0 | ... U41: ='Para Histograma'!AC613 -> 0
C42: Act.
B43: ='Para Histograma'!D614 -> BOMBA PARA PRUEBAS HIDROSTÁTICAS | C43: Plan | D43: ='Para Histograma'!L614 -> 0 | E43: ='Para Histograma'!M614 -> 0 | F43: ='Para Histograma'!N614 -> 0 | G43: ='Para Histograma'!O614 -> 0 | H43: ='Para Histograma'!P614 -> 0 | I43: ='Para Histograma'!Q614 -> 0 | J43: ='Para Histograma'!R614 -> 0 | K43: ='Para Histograma'!S614 -> 0 | ... U43: ='Para Histograma'!AC614 -> 0
C44: Act.
...
