Workbook
Name \0: #REF!
Name \0: !#REF!
Name \00: #REF!
Name \1: #REF!
Name \44333: #REF!
Name \a: #N/A
Name \add9a: #REF!
Name \b: #REF!
Name \b: !#REF!
Name \c: #REF!
Name \c: !#REF!
Name \Convergence: 1.79769313486231E+59
Name \d: #REF!
Name \d: !#REF!
Name \D2: #N/A
Name \DA: #N/A
Name \DA2: #N/A
Name \e: #N/A
Name \f: #REF!
Name \f: !#REF!
Name \g: #REF!
Name \g: !#REF!
Name \GA: #N/A
Name \h: #REF!
Name \h: !#REF!
Name \i: #REF!
Name \i: !#REF!
Name \IA: #N/A
Name \IterationCount: 0
Name \j: #REF!
Name \JA: #N/A
Name \K: #REF!
Name \K: !#REF!
Name \L: #REF!
Name \L: !#REF!
Name \L0: #N/A
Name \L1: #N/A
Name \L11: #N/A
Name \L2: #N/A
Name \m: #REF!
Name \m: !#REF!
Name \MACROS: #REF!
Name \MENU: #REF!
Name \n: #REF!
Name \n: !#REF!
Name \ñ: #REF!
Name \ñ: !#REF!
Name \O: #REF!
Name \P: #REF!
Name \P: !#REF!
Name \PRECIOS: #REF!
Name \PRECIOS: !#REF!
Name \q: #REF!
Name \q: !#REF!
Name \r: #N/A
Name \s: #REF!
Name \s: !#REF!
Name \SA: #N/A
Name \SALVAR: #N/A
Name \t: #REF!

Sheet CARÁTULA de QPS
M1: SUPERINTENDENCIA DE INGENIERÍA | AJ1: CÓDIGO: PCS-IN-FO-019 Ver. 01 / 22-May-2022
B3: PROYECTOS DE CAPITAL SOSTENIBLE
M4: CANTIDADES Y PRECIOS OFERTADOS (QPS) | AJ4: CÓDIGO DE DOC.:
AJ5: =P13&"_"&D51 -> CRD-QPS-11760-G-33-4001_C
C7: =+"WBS Nº: "&AX7 -> WBS Nº: 1760 | AX7: 1760 | AY7: .
C10: AÑO: 2025
C13: QPS Nº: | P13: CRD-QPS-11760-G-33-4001
C16: CANTIDADES Y PRECIOS OFERTADOS (QPS)
B23: SISTEMA DE DOSIFICACIÓN DE FLOCULANTE AWTP - PL
C28: DISCIPLINA: GENERAL
C31: Preparado por:
C32: GRUPO CREDCO S.A.C.
C35: Aprobado por:
C37: Ingeniero Líder | U37: : | V37: Raul Gilio
C38: Gerente de Proyecto - CREDCO | U38: : | V38: Victor Soto
C39: Gerente de Proyecto - MYSRL | U39: : | V39: Victor Castillo
C41: Rev. | F41: Elaborado | L41: Emitido para | AB41: Fecha | AG41: Revisado | AM41: Aprobado
C42: A | F42: C.M./G.C./F.D./A.B. | L42: Emitido para revisión interna | AB42: 45869 | AG42: M.T. | AM42: V.S.
C43: B | F43: C.M./G.C./F.D./A.B. | L43: Emitido para revisión del cliente | AB43: 45870 | AG43: M.T. | AM43: V.S.
C44: C | F44: C.M./G.C./F.D./A.B. | L44: Emitido para revisión del cliente | AB44: 45889 | AG44: M.T. | AM44: V.S.
C46: Comentarios:
D51: C

Sheet CARATULA CPQ - COLUMBITO

Sheet QPS
B1: PROYECTOS DE CAPITAL SOSTENIBLE | G1: SUPERINTENDENCIA DE INGENIERÍA | S1: Código: PCS-IN-FO-008 Vers 01 / 23-May-2022 | X1: =TEXT(C16,"0.0000") -> 1.0101
X2: =IF(ISNUMBER(C16),TEXT(C16,"0.0000"),C16) -> 1.0101
X3: =SUBSTITUTE(TEXT(C16,"0.0000"),".","") -> 10101
G4: CANTIDADES Y PRECIOS OFERTADOS (QPS) | S4: =+"CÓDIGO DE DOC. CRD-QPS-11760-G-33-4001_"&'CARÁTULA de QPS'!D51 -> CÓDIGO DE DOC. CRD-QPS-11760-G-33-4001_C | X4: =TEXT(C15,"0.0000") -> 1.0100
B5: ÁREA: | E5: PAMPA LARGA | T5: QPS No. : | U5: =+'CARÁTULA de QPS'!P13 -> CRD-QPS-11760-G-33-4001 | X5: =TEXT(C38,"0.0000") -> 2.0410
B6: CÓDIGO DE FACILIDAD: | E6: - | T6: REV. : | U6: =+'CARÁTULA de QPS'!D51 -> C | X6: =REPLACE(TEXT(C16,"0.0000"),5,0,".") -> 1.01.01
B7: WBS No.: | E7: 1760 | T7: FECHA: | U7: =+'CARÁTULA de QPS'!AB44 -> 45889 | X7: =SUMIFS(APU!O:O,APU!A:A,REPLACE(TEXT(C16,"0.0000"),5,0,"."),APU!G:G,"hh") -> 200
B8: FCR No.: | E8: - | T8: ELABORADO POR: | U8: =+'CARÁTULA de QPS'!F42 -> C.M./G.C./F.D./A.B. | X8: =SUMIFS(APU!O:O,APU!A:A,C120,APU!G:G,"hh") -> 32.16
B9: SOW No.: | E9: CRD-SOW-11760-G-33-4001
B11: Artículo de Pago | C11: Ítem | D11: CÓDIGO DE COSTO | G11: Descripción de la Actividad | N11: Tamaño | O11: Clase | Q11: Estado alcance | R11: Especialidad | S11: Cantidad | U11: Precio | AK11: Rótulos suministro (auxiliar) | AM11: Mapeo especialidad (auxiliar)
D12: Código de Área | E12: Código de Sub Área | F12: Código de Actividad | T12: Unidad | U12: Unitario | V12: Oferta Total | AK12: Suministro MY | AM12: GENERAL | AN12: Civil
T13: Básica | U13: Ofertado | W13: hh | AB13: hh | AC13: Rendimiento /DIA | AD13: Duración (días) | AE13: Cód. norm. | AG13: % Avance | AH13: HH ganadas | AI13: Clave única | AK13: Suministro Contratista | AM13: CIVIL | AN13: Civil
B14: GENERAL | AM14: MECÁNICA - TUBERIAS | AN14: Mecanica
B15: 8.1 | C15: 1.01 | D15: - | E15: - | F15: - | G15: TRABAJOS PRELIMINARES | N15: - | O15: - | P15: =IF(TRIM($G15)="","",TRIM($G15)&IF(OR(TRIM($N15)="",TRIM($N15)="-"),""," - "&TRIM($N15))&IF(OR(TRIM($O15)="",TRIM($O15)="-"),""," - "&TRIM($O15))&IF(ISNUMBER(SEARCH("SUMINISTRO",$G15))," - "&$AK$13,IF(ISNUMBER(SEARCH("MONTAJE",$G15))," - "&$AK$12,""))) -> TRABAJOS PRELIMINARES | Q15: En alcance | R15: {=IF($G15="","",IFERROR(VLOOKUP(LOOKUP(2,1/(($B$14:$B15<>"")*($C$14:$C15="")),$B$14:$B15),$AM$12:$AN$16,2,FALSE),""))} -> Civil | AB15: {=IF($S15="","",SUMIFS(APU!$O:$O,APU!$A:$A,IF(ISNUMBER($C15),REPLACE(TEXT($C15,"0.0000"),5,0,"."),$C15),APU!$G:$G,"hh")/MAX(1,SUMPRODUCT(($C$15:$C$262=$C15)*($S$15:$S$262<>""))))} | AC15: =IF($S15="","",IFERROR(VLOOKUP($AE15,APU!$V:$X,2,FALSE),"")) | AD15: =IF(OR($S15="",$AC15="",N($AC15)=0),"",$S15/$AC15) | AE15: =IF($C15="","",IF(ISNUMBER($C15),REPLACE(TEXT($C15,"0.0000"),5,0,"."),$C15)) -> 1.01.00 | AH15: =IF($S15="","",$AB15*N($AG15)) | AI15: =IF($S15="","",$AE15&IF(TRIM($N15)="",""," | "&TRIM($N15))&IF(OR(TRIM($O15)="",TRIM($O15)="-"),""," | "&TRIM($O15))) | AM15: ELECTRICIDAD | AN15: Electrica
B16: 8.1.1 | C16: =+C15+0.0001 -> 1.0101 | D16: - | E16: - | F16: - | G16: Movilización y desmovilización | N16: - | O16: - | P16: =IF(TRIM($G16)="","",TRIM($G16)&IF(OR(TRIM($N16)="",TRIM($N16)="-"),""," - "&TRIM($N16))&IF(OR(TRIM($O16)="",TRIM($O16)="-"),""," - "&TRIM($O16))&IF(ISNUMBER(SEARCH("SUMINISTRO",$G16))," - "&$AK$13,IF(ISNUMBER(SEARCH("MONTAJE",$G16))," - "&$AK$12,""))) -> Movilización y desmovilización | Q16: En alcance | R16: {=IF($G16="","",IFERROR(VLOOKUP(LOOKUP(2,1/(($B$14:$B16<>"")*($C$14:$C16="")),$B$14:$B16),$AM$12:$AN$16,2,FALSE),""))} -> Civil | S16: 1 | T16: Glb. | U16: =APU!K3 -> 6797.26 | V16: =U16*S16 -> 6797.26 | AB16: {=IF($S16="","",SUMIFS(APU!$O:$O,APU!$A:$A,IF(ISNUMBER($C16),REPLACE(TEXT($C16,"0.0000"),5,0,"."),$C16),APU!$G:$G,"hh")/MAX(1,SUMPRODUCT(($C$15:$C$262=$C16)*($S$15:$S$262<>""))))} -> 200 | AC16: =IF($S16="","",IFERROR(VLOOKUP($AE16,APU!$V:$X,2,FALSE),"")) -> 0.2 | AD16: =IF(OR($S16="",$AC16="",N($AC16)=0),"",$S16/$AC16) -> 5 | AE16: =IF($C16="","",IF(ISNUMBER($C16),REPLACE(TEXT($C16,"0.0000"),5,0,"."),$C16)) -> 1.01.01 | AH16: =IF($S16="","",$AB16*N($AG16)) -> 0 | AI16: =IF($S16="","",$AE16&IF(TRIM($N16)="",""," | "&TRIM($N16))&IF(OR(TRIM($O16)="",TRIM($O16)="-"),""," | "&TRIM($O16))) -> 1.01.01 | - | AM16: INSTRUMENTACIÓN | AN16: Electrica
B17: 8.1.2 | C17: =+C16+0.0001 -> 1.0102 | D17: - | E17: - | F17: - | G17: Trazo y replanteo (preliminar y durante la obra) | N17: - | O17: - | P17: =IF(TRIM($G17)="","",TRIM($G17)&IF(OR(TRIM($N17)="",TRIM($N17)="-"),""," - "&TRIM($N17))&IF(OR(TRIM($O17)="",TRIM($O17)="-"),""," - "&TRIM($O17))&IF(ISNUMBER(SEARCH("SUMINISTRO",$G17))," - "&$AK$13,IF(ISNUMBER(SEARCH("MONTAJE",$G17))," - "&$AK$12,""))) -> Trazo y replanteo (preliminar y durante la obra) | Q17: En alcance | R17: {=IF($G17="","",IFERROR(VLOOKUP(LOOKUP(2,1/(($B$14:$B17<>"")*($C$14:$C17="")),$B$14:$B17),$AM$12:$AN$16,2,FALSE),""))} -> Civil | S17: 1 | T17: Glb. | U17: =APU!K16 -> 518.25029 | V17: =U17*S17 -> 518.25029 | AB17: {=IF($S17="","",SUMIFS(APU!$O:$O,APU!$A:$A,IF(ISNUMBER($C17),REPLACE(TEXT($C17,"0.0000"),5,0,"."),$C17),APU!$G:$G,"hh")/MAX(1,SUMPRODUCT(($C$15:$C$262=$C17)*($S$15:$S$262<>""))))} -> 48 | AC17: =IF($S17="","",IFERROR(VLOOKUP($AE17,APU!$V:$X,2,FALSE),"")) -> 0.5 | AD17: =IF(OR($S17="",$AC17="",N($AC17)=0),"",$S17/$AC17) -> 2 | AE17: =IF($C17="","",IF(ISNUMBER($C17),REPLACE(TEXT($C17,"0.0000"),5,0,"."),$C17)) -> 1.01.02 | AH17: =IF($S17="","",$AB17*N($AG17)) -> 0 | AI17: =IF($S17="","",$AE17&IF(TRIM($N17)="",""," | "&TRIM($N17))&IF(OR(TRIM($O17)="",TRIM($O17)="-"),""," | "&TRIM($O17))) -> 1.01.02 | -
B18: 8.1.3 | C18: =+C17+0.0001 -> 1.0103 | D18: - | E18: - | F18: - | G18: Limpieza del área de trabajo | N18: - | O18: - | P18: =IF(TRIM($G18)="","",TRIM($G18)&IF(OR(TRIM($N18)="",TRIM($N18)="-"),""," - "&TRIM($N18))&IF(OR(TRIM($O18)="",TRIM($O18)="-"),""," - "&TRIM($O18))&IF(ISNUMBER(SEARCH("SUMINISTRO",$G18))," - "&$AK$13,IF(ISNUMBER(SEARCH("MONTAJE",$G18))," - "&$AK$12,""))) -> Limpieza del área de trabajo | Q18: En alcance | R18: {=IF($G18="","",IFERROR(VLOOKUP(LOOKUP(2,1/(($B$14:$B18<>"")*($C$14:$C18="")),$B$14:$B18),$AM$12:$AN$16,2,FALSE),""))} -> Civil | S18: 1 | T18: Glb. | U18: =APU!K33 -> 236.976 | V18: =U18*S18 -> 236.976 | AB18: {=IF($S18="","",SUMIFS(APU!$O:$O,APU!$A:$A,IF(ISNUMBER($C18),REPLACE(TEXT($C18,"0.0000"),5,0,"."),$C18),APU!$G:$G,"hh")/MAX(1,SUMPRODUCT(($C$15:$C$262=$C18)*($S$15:$S$262<>""))))} -> 33.6 | AC18: =IF($S18="","",IFERROR(VLOOKUP($AE18,APU!$V:$X,2,FALSE),"")) -> 1 | AD18: =IF(OR($S18="",$AC18="",N($AC18)=0),"",$S18/$AC18) -> 1 | AE18: =IF($C18="","",IF(ISNUMBER($C18),REPLACE(TEXT($C18,"0.0000"),5,0,"."),$C18)) -> 1.01.03 | AH18: =IF($S18="","",$AB18*N($AG18)) -> 0 | AI18: =IF($S18="","",$AE18&IF(TRIM($N18)="",""," | "&TRIM($N18))&IF(OR(TRIM($O18)="",TRIM($O18)="-"),""," | "&TRIM($O18))) -> 1.01.03 | -
B19: CIVIL | AB19: {=IF($S19="","",SUMIFS(APU!$O:$O,APU!$A:$A,IF(ISNUMBER($C19),REPLACE(TEXT($C19,"0.0000"),5,0,"."),$C19),APU!$G:$G,"hh")/MAX(1,SUMPRODUCT(($C$15:$C$262=$C19)*($S$15:$S$262<>""))))} | AC19: =IF($S19="","",IFERROR(VLOOKUP($AE19,APU!$V:$X,2,FALSE),"")) | AD19: =IF(OR($S19="",$AC19="",N($AC19)=0),"",$S19/$AC19) | AE19: =IF($C19="","",IF(ISNUMBER($C19),REPLACE(TEXT($C19,"0.0000"),5,0,"."),$C19)) | AH19: =IF($S19="","",$AB19*N($AG19)) | AI19: =IF($S19="","",$AE19&IF(TRIM($N19)="",""," | "&TRIM($N19))&IF(OR(TRIM($O19)="",TRIM($O19)="-"),""," | "&TRIM($O19)))
B20: 8.2.1 | C20: 2.01 | D20: - | E20: - | F20: - | G20: DEMOLICIÓN | N20: - | O20: - | P20: =IF(TRIM($G20)="","",TRIM($G20)&IF(OR(TRIM($N20)="",TRIM($N20)="-"),""," - "&TRIM($N20))&IF(OR(TRIM($O20)="",TRIM($O20)="-"),""," - "&TRIM($O20))&IF(ISNUMBER(SEARCH("SUMINISTRO",$G20))," - "&$AK$13,IF(ISNUMBER(SEARCH("MONTAJE",$G20))," - "&$AK$12,""))) -> DEMOLICIÓN | Q20: En alcance | R20: {=IF($G20="","",IFERROR(VLOOKUP(LOOKUP(2,1/(($B$14:$B20<>"")*($C$14:$C20="")),$B$14:$B20),$AM$12:$AN$16,2,FALSE),""))} -> Civil | AB20: {=IF($S20="","",SUMIFS(APU!$O:$O,APU!$A:$A,IF(ISNUMBER($C20),REPLACE(TEXT($C20,"0.0000"),5,0,"."),$C20),APU!$G:$G,"hh")/MAX(1,SUMPRODUCT(($C$15:$C$262=$C20)*($S$15:$S$262<>""))))} | AC20: =IF($S20="","",IFERROR(VLOOKUP($AE20,APU!$V:$X,2,FALSE),"")) | AD20: =IF(OR($S20="",$AC20="",N($AC20)=0),"",$S20/$AC20) | AE20: =IF($C20="","",IF(ISNUMBER($C20),REPLACE(TEXT($C20,"0.0000"),5,0,"."),$C20)) -> 2.01.00 | AH20: =IF($S20="","",$AB20*N($AG20)) | AI20: =IF($S20="","",$AE20&IF(TRIM($N20)="",""," | "&TRIM($N20))&IF(OR(TRIM($O20)="",TRIM($O20)="-"),""," | "&TRIM($O20)))
B21: 8.2.1 | C21: =+C20+0.0001 -> 2.0101 | D21: - | E21: - | F21: - | G21: Demolición de bases e = 50 cm | P21: =IF(TRIM($G21)="","",TRIM($G21)&IF(OR(TRIM($N21)="",TRIM($N21)="-"),""," - "&TRIM($N21))&IF(OR(TRIM($O21)="",TRIM($O21)="-"),""," - "&TRIM($O21))&IF(ISNUMBER(SEARCH("SUMINISTRO",$G21))," - "&$AK$13,IF(ISNUMBER(SEARCH("MONTAJE",$G21))," - "&$AK$12,""))) -> Demolición de bases e = 50 cm | Q21: En alcance | R21: {=IF($G21="","",IFERROR(VLOOKUP(LOOKUP(2,1/(($B$14:$B21<>"")*($C$14:$C21="")),$B$14:$B21),$AM$12:$AN$16,2,FALSE),""))} -> Civil | S21: 1.28 | T21: m3 | U21: =APU!K41 -> 420.851 | V21: =U21*S21 -> 538.68928 | AB21: {=IF($S21="","",SUMIFS(APU!$O:$O,APU!$A:$A,IF(ISNUMBER($C21),REPLACE(TEXT($C21,"0.0000"),5,0,"."),$C21),APU!$G:$G,"hh")/MAX(1,SUMPRODUCT(($C$15:$C$262=$C21)*($S$15:$S$262<>""))))} -> 53.76 | AC21: =IF($S21="","",IFERROR(VLOOKUP($AE21,APU!$V:$X,2,FALSE),"")) -> 0.4 | AD21: =IF(OR($S21="",$AC21="",N($AC21)=0),"",$S21/$AC21) -> 3.2 | AE21: =IF($C21="","",IF(ISNUMBER($C21),REPLACE(TEXT($C21,"0.0000"),5,0,"."),$C21)) -> 2.01.01 | AH21: =IF($S21="","",$AB21*N($AG21)) -> 0 | AI21: =IF($S21="","",$AE21&IF(TRIM($N21)="",""," | "&TRIM($N21))&IF(OR(TRIM($O21)="",TRIM($O21)="-"),""," | "&TRIM($O21))) -> 2.01.01
B22: 8.2.2 | C22: 2.02 | D22: - | E22: - | F22: - | G22: CONCRETO SIMPLE | P22: =IF(TRIM($G22)="","",TRIM($G22)&IF(OR(TRIM($N22)="",TRIM($N22)="-"),""," - "&TRIM($N22))&IF(OR(TRIM($O22)="",TRIM($O22)="-"),""," - "&TRIM($O22))&IF(ISNUMBER(SEARCH("SUMINISTRO",$G22))," - "&$AK$13,IF(ISNUMBER(SEARCH("MONTAJE",$G22))," - "&$AK$12,""))) -> CONCRETO SIMPLE | Q22: En alcance | R22: {=IF($G22="","",IFERROR(VLOOKUP(LOOKUP(2,1/(($B$14:$B22<>"")*($C$14:$C22="")),$B$14:$B22),$AM$12:$AN$16,2,FALSE),""))} -> Civil | AB22: {=IF($S22="","",SUMIFS(APU!$O:$O,APU!$A:$A,IF(ISNUMBER($C22),REPLACE(TEXT($C22,"0.0000"),5,0,"."),$C22),APU!$G:$G,"hh")/MAX(1,SUMPRODUCT(($C$15:$C$262=$C22)*($S$15:$S$262<>""))))} | AC22: =IF($S22="","",IFERROR(VLOOKUP($AE22,APU!$V:$X,2,FALSE),"")) | AD22: =IF(OR($S22="",$AC22="",N($AC22)=0),"",$S22/$AC22) | AE22: =IF($C22="","",IF(ISNUMBER($C22),REPLACE(TEXT($C22,"0.0000"),5,0,"."),$C22)) -> 2.02.00 | AH22: =IF($S22="","",$AB22*N($AG22)) | AI22: =IF($S22="","",$AE22&IF(TRIM($N22)="",""," | "&TRIM($N22))&IF(OR(TRIM($O22)="",TRIM($O22)="-"),""," | "&TRIM($O22)))
B23: 8.2.2 | C23: =+C22+0.0001 -> 2.0201 | D23: - | E23: - | F23: - | G23: Concreto simple f'c=100 kg/cm2 | P23: =IF(TRIM($G23)="","",TRIM($G23)&IF(OR(TRIM($N23)="",TRIM($N23)="-"),""," - "&TRIM($N23))&IF(OR(TRIM($O23)="",TRIM($O23)="-"),""," - "&TRIM($O23))&IF(ISNUMBER(SEARCH("SUMINISTRO",$G23))," - "&$AK$13,IF(ISNUMBER(SEARCH("MONTAJE",$G23))," - "&$AK$12,""))) -> Concreto simple f'c=100 kg/cm2 | Q23: En alcance | R23: {=IF($G23="","",IFERROR(VLOOKUP(LOOKUP(2,1/(($B$14:$B23<>"")*($C$14:$C23="")),$B$14:$B23),$AM$12:$AN$16,2,FALSE),""))} -> Civil | S23: =(0.9*0.45+2*0.5*1.2)*0.05 -> 0.08025 | T23: m3 | U23: =APU!K57 -> 268.55525 | V23: =U23*S23 -> 21.551559 | AB23: {=IF($S23="","",SUMIFS(APU!$O:$O,APU!$A:$A,IF(ISNUMBER($C23),REPLACE(TEXT($C23,"0.0000"),5,0,"."),$C23),APU!$G:$G,"hh")/MAX(1,SUMPRODUCT(($C$15:$C$262=$C23)*($S$15:$S$262<>""))))} -> 0.35096 | AC23: =IF($S23="","",IFERROR(VLOOKUP($AE23,APU!$V:$X,2,FALSE),"")) -> 15 | AD23: =IF(OR($S23="",$AC23="",N($AC23)=0),"",$S23/$AC23) -> 0.00535 | AE23: =IF($C23="","",IF(ISNUMBER($C23),REPLACE(TEXT($C23,"0.0000"),5,0,"."),$C23)) -> 2.02.01 | AH23: =IF($S23="","",$AB23*N($AG23)) -> 0 | AI23: =IF($S23="","",$AE23&IF(TRIM($N23)="",""," | "&TRIM($N23))&IF(OR(TRIM($O23)="",TRIM($O23)="-"),""," | "&TRIM($O23))) -> 2.02.01
B24: 8.2.3 | C24: 2.03 | D24: - | E24: - | F24: - | G24: CONCRETO ARMADO | P24: =IF(TRIM($G24)="","",TRIM($G24)&IF(OR(TRIM($N24)="",TRIM($N24)="-"),""," - "&TRIM($N24))&IF(OR(TRIM($O24)="",TRIM($O24)="-"),""," - "&TRIM($O24))&IF(ISNUMBER(SEARCH("SUMINISTRO",$G24))," - "&$AK$13,IF(ISNUMBER(SEARCH("MONTAJE",$G24))," - "&$AK$12,""))) -> CONCRETO ARMADO | Q24: En alcance | R24: {=IF($G24="","",IFERROR(VLOOKUP(LOOKUP(2,1/(($B$14:$B24<>"")*($C$14:$C24="")),$B$14:$B24),$AM$12:$AN$16,2,FALSE),""))} -> Civil | AB24: {=IF($S24="","",SUMIFS(APU!$O:$O,APU!$A:$A,IF(ISNUMBER($C24),REPLACE(TEXT($C24,"0.0000"),5,0,"."),$C24),APU!$G:$G,"hh")/MAX(1,SUMPRODUCT(($C$15:$C$262=$C24)*($S$15:$S$262<>""))))} | AC24: =IF($S24="","",IFERROR(VLOOKUP($AE24,APU!$V:$X,2,FALSE),"")) | AD24: =IF(OR($S24="",$AC24="",N($AC24)=0),"",$S24/$AC24) | AE24: =IF($C24="","",IF(ISNUMBER($C24),REPLACE(TEXT($C24,"0.0000"),5,0,"."),$C24)) -> 2.03.00 | AH24: =IF($S24="","",$AB24*N($AG24)) | AI24: =IF($S24="","",$AE24&IF(TRIM($N24)="",""," | "&TRIM($N24))&IF(OR(TRIM($O24)="",TRIM($O24)="-"),""," | "&TRIM($O24)))
B25: 8.2.3 | C25: =+C24+0.0001 -> 2.0301 | D25: - | E25: - | F25: - | G25: Concreto f'c=25MPa, Cemento tipo HS | P25: =IF(TRIM($G25)="","",TRIM($G25)&IF(OR(TRIM($N25)="",TRIM($N25)="-"),""," - "&TRIM($N25))&IF(OR(TRIM($O25)="",TRIM($O25)="-"),""," - "&TRIM($O25))&IF(ISNUMBER(SEARCH("SUMINISTRO",$G25))," - "&$AK$13,IF(ISNUMBER(SEARCH("MONTAJE",$G25))," - "&$AK$12,""))) -> Concreto f'c=25MPa, Cemento tipo HS | Q25: En alcance | R25: {=IF($G25="","",IFERROR(VLOOKUP(LOOKUP(2,1/(($B$14:$B25<>"")*($C$14:$C25="")),$B$14:$B25),$AM$12:$AN$16,2,FALSE),""))} -> Civil | S25: =(0.9*0.45*0.5+2*0.5*1.2*0.5)+0.0675+0.027 -> 0.897 | T25: m3 | U25: =APU!K75 -> 321.20525 | V25: =U25*S25 -> 288.12111 | AB25: {=IF($S25="","",SUMIFS(APU!$O:$O,APU!$A:$A,IF(ISNUMBER($C25),REPLACE(TEXT($C25,"0.0000"),5,0,"."),$C25),APU!$G:$G,"hh")/MAX(1,SUMPRODUCT(($C$15:$C$262=$C25)*($S$15:$S$262<>""))))} -> 3.92288 | AC25: =IF($S25="","",IFERROR(VLOOKUP($AE25,APU!$V:$X,2,FALSE),"")) -> 15 | AD25: =IF(OR($S25="",$AC25="",N($AC25)=0),"",$S25/$AC25) -> 0.0598 | AE25: =IF($C25="","",IF(ISNUMBER($C25),REPLACE(TEXT($C25,"0.0000"),5,0,"."),$C25)) -> 2.03.01 | AH25: =IF($S25="","",$AB25*N($AG25)) -> 0 | AI25: =IF($S25="","",$AE25&IF(TRIM($N25)="",""," | "&TRIM($N25))&IF(OR(TRIM($O25)="",TRIM($O25)="-"),""," | "&TRIM($O25))) -> 2.03.01
B26: 8.2.3 | C26: =+C25+0.0001 -> 2.0302 | D26: - | E26: - | F26: - | G26: Encofrado y desencofrado | P26: =IF(TRIM($G26)="","",TRIM($G26)&IF(OR(TRIM($N26)="",TRIM($N26)="-"),""," - "&TRIM($N26))&IF(OR(TRIM($O26)="",TRIM($O26)="-"),""," - "&TRIM($O26))&IF(ISNUMBER(SEARCH("SUMINISTRO",$G26))," - "&$AK$13,IF(ISNUMBER(SEARCH("MONTAJE",$G26))," - "&$AK$12,""))) -> Encofrado y desencofrado | Q26: En alcance | R26: {=IF($G26="","",IFERROR(VLOOKUP(LOOKUP(2,1/(($B$14:$B26<>"")*($C$14:$C26="")),$B$14:$B26),$AM$12:$AN$16,2,FALSE),""))} -> Civil | S26: =(0.9+0.45+2*(0.5+1.2))+1.8+0.45 -> 7 | T26: m2 | U26: =APU!K96 -> 29.719167 | V26: =U26*S26 -> 208.03417 | AB26: {=IF($S26="","",SUMIFS(APU!$O:$O,APU!$A:$A,IF(ISNUMBER($C26),REPLACE(TEXT($C26,"0.0000"),5,0,"."),$C26),APU!$G:$G,"hh")/MAX(1,SUMPRODUCT(($C$15:$C$262=$C26)*($S$15:$S$262<>""))))} -> 6.8444444 | AC26: =IF($S26="","",IFERROR(VLOOKUP($AE26,APU!$V:$X,2,FALSE),"")) -> 18 | AD26: =IF(OR($S26="",$AC26="",N($AC26)=0),"",$S26/$AC26) -> 0.38888889 | AE26: =IF($C26="","",IF(ISNUMBER($C26),REPLACE(TEXT($C26,"0.0000"),5,0,"."),$C26)) -> 2.03.02 | AH26: =IF($S26="","",$AB26*N($AG26)) -> 0 | AI26: =IF($S26="","",$AE26&IF(TRIM($N26)="",""," | "&TRIM($N26))&IF(OR(TRIM($O26)="",TRIM($O26)="-"),""," | "&TRIM($O26))) -> 2.03.02
B27: 8.2.3 | C27: =+C26+0.0001 -> 2.0303 | D27: - | E27: - | F27: - | G27: Acero de Refuerzo (ASTM A-615 G 60, fy = 420 MPa) | P27: =IF(TRIM($G27)="","",TRIM($G27)&IF(OR(TRIM($N27)="",TRIM($N27)="-"),""," - "&TRIM($N27))&IF(OR(TRIM($O27)="",TRIM($O27)="-"),""," - "&TRIM($O27))&IF(ISNUMBER(SEARCH("SUMINISTRO",$G27))," - "&$AK$13,IF(ISNUMBER(SEARCH("MONTAJE",$G27))," - "&$AK$12,""))) -> Acero de Refuerzo (ASTM A-615 G 60, fy = 420 MPa) | Q27: En alcance | R27: {=IF($G27="","",IFERROR(VLOOKUP(LOOKUP(2,1/(($B$14:$B27<>"")*($C$14:$C27="")),$B$14:$B27),$AM$12:$AN$16,2,FALSE),""))} -> Civil | S27: =((0.45*2+1)*5+(1.8+1)*3+(0.5*2+1)*6+(2.4+1)*3)*1.55+23 -> 85.155 | T27: kg | U27: =APU!K117 -> 2.4012752 | V27: =U27*S27 -> 204.48059 | AB27: {=IF($S27="","",SUMIFS(APU!$O:$O,APU!$A:$A,IF(ISNUMBER($C27),REPLACE(TEXT($C27,"0.0000"),5,0,"."),$C27),APU!$G:$G,"hh")/MAX(1,SUMPRODUCT(($C$15:$C$262=$C27)*($S$15:$S$262<>""))))} -> 5.994912 | AC27: =IF($S27="","",IFERROR(VLOOKUP($AE27,APU!$V:$X,2,FALSE),"")) -> 250 | AD27: =IF(OR($S27="",$AC27="",N($AC27)=0),"",$S27/$AC27) -> 0.34062 | AE27: =IF($C27="","",IF(ISNUMBER($C27),REPLACE(TEXT($C27,"0.0000"),5,0,"."),$C27)) -> 2.03.03 | AH27: =IF($S27="","",$AB27*N($AG27)) -> 0 | AI27: =IF($S27="","",$AE27&IF(TRIM($N27)="",""," | "&TRIM($N27))&IF(OR(TRIM($O27)="",TRIM($O27)="-"),""," | "&TRIM($O27))) -> 2.03.03
B28: 8.2.4 | C28: 2.04 | D28: - | E28: - | F28: - | G28: OTROS | P28: =IF(TRIM($G28)="","",TRIM($G28)&IF(OR(TRIM($N28)="",TRIM($N28)="-"),""," - "&TRIM($N28))&IF(OR(TRIM($O28)="",TRIM($O28)="-"),""," - "&TRIM($O28))&IF(ISNUMBER(SEARCH("SUMINISTRO",$G28))," - "&$AK$13,IF(ISNUMBER(SEARCH("MONTAJE",$G28))," - "&$AK$12,""))) -> OTROS | Q28: En alcance | R28: {=IF($G28="","",IFERROR(VLOOKUP(LOOKUP(2,1/(($B$14:$B28<>"")*($C$14:$C28="")),$B$14:$B28),$AM$12:$AN$16,2,FALSE),""))} -> Civil | AB28: {=IF($S28="","",SUMIFS(APU!$O:$O,APU!$A:$A,IF(ISNUMBER($C28),REPLACE(TEXT($C28,"0.0000"),5,0,"."),$C28),APU!$G:$G,"hh")/MAX(1,SUMPRODUCT(($C$15:$C$262=$C28)*($S$15:$S$262<>""))))} | AC28: =IF($S28="","",IFERROR(VLOOKUP($AE28,APU!$V:$X,2,FALSE),"")) | AD28: =IF(OR($S28="",$AC28="",N($AC28)=0),"",$S28/$AC28) | AE28: =IF($C28="","",IF(ISNUMBER($C28),REPLACE(TEXT($C28,"0.0000"),5,0,"."),$C28)) -> 2.04.00 | AH28: =IF($S28="","",$AB28*N($AG28)) | AI28: =IF($S28="","",$AE28&IF(TRIM($N28)="",""," | "&TRIM($N28))&IF(OR(TRIM($O28)="",TRIM($O28)="-"),""," | "&TRIM($O28)))
B29: 8.2.4 | C29: =+C28+0.0001 -> 2.0401 | D29: - | E29: - | F29: - | G29: Varilla roscada tipo HAS o equivalente tecnico Ø 1" L=30cm, contratuerca y arandela, tipo de anclaje quimico adhesivo HIT-HY 200 o equivalente tecnico | P29: =IF(TRIM($G29)="","",TRIM($G29)&IF(OR(TRIM($N29)="",TRIM($N29)="-"),""," - "&TRIM($N29))&IF(OR(TRIM($O29)="",TRIM($O29)="-"),""," - "&TRIM($O29))&IF(ISNUMBER(SEARCH("SUMINISTRO",$G29))," - "&$AK$13,IF(ISNUMBER(SEARCH("MONTAJE",$G29))," - "&$AK$12,""))) -> Varilla roscada tipo HAS o equivalente tecnico Ø 1" L=30cm, contratuerca y arandela, tipo de anclaje quimico adhesivo HIT-HY 200 o equivalente tecnico | Q29: En alcance | R29: {=IF($G29="","",IFERROR(VLOOKUP(LOOKUP(2,1/(($B$14:$B29<>"")*($C$14:$C29="")),$B$14:$B29),$AM$12:$AN$16,2,FALSE),""))} -> Civil | S29: 12 | T29: UND | U29: =APU!K135 -> 117.23702 | V29: =U29*S29 -> 1406.8442 | AB29: {=IF($S29="","",SUMIFS(APU!$O:$O,APU!$A:$A,IF(ISNUMBER($C29),REPLACE(TEXT($C29,"0.0000"),5,0,"."),$C29),APU!$G:$G,"hh")/MAX(1,SUMPRODUCT(($C$15:$C$262=$C29)*($S$15:$S$262<>""))))} -> 10.08 | AC29: =IF($S29="","",IFERROR(VLOOKUP($AE29,APU!$V:$X,2,FALSE),"")) -> 20 | AD29: =IF(OR($S29="",$AC29="",N($AC29)=0),"",$S29/$AC29) -> 0.6 | AE29: =IF($C29="","",IF(ISNUMBER($C29),REPLACE(TEXT($C29,"0.0000"),5,0,"."),$C29)) -> 2.04.01 | AH29: =IF($S29="","",$AB29*N($AG29)) -> 0 | AI29: =IF($S29="","",$AE29&IF(TRIM($N29)="",""," | "&TRIM($N29))&IF(OR(TRIM($O29)="",TRIM($O29)="-"),""," | "&TRIM($O29))) -> 2.04.01
B30: 8.2.4 | C30: =+C29+0.0001 -> 2.0402 | D30: - | E30: - | F30: - | G30: Juntas de expansión de acuerdo al plano estándar CRD-DWG-11760-1-33-4002 | P30: =IF(TRIM($G30)="","",TRIM($G30)&IF(OR(TRIM($N30)="",TRIM($N30)="-"),""," - "&TRIM($N30))&IF(OR(TRIM($O30)="",TRIM($O30)="-"),""," - "&TRIM($O30))&IF(ISNUMBER(SEARCH("SUMINISTRO",$G30))," - "&$AK$13,IF(ISNUMBER(SEARCH("MONTAJE",$G30))," - "&$AK$12,""))) -> Juntas de expansión de acuerdo al plano estándar CRD-DWG-11760-1-33-4002 | Q30: En alcance | R30: {=IF($G30="","",IFERROR(VLOOKUP(LOOKUP(2,1/(($B$14:$B30<>"")*($C$14:$C30="")),$B$14:$B30),$AM$12:$AN$16,2,FALSE),""))} -> Civil | S30: =1.8+0.9+(1+2.4)*2 -> 9.5 | T30: m | U30: =+APU!K152 -> 22.76202 | V30: =U30*S30 -> 216.23919 | AB30: {=IF($S30="","",SUMIFS(APU!$O:$O,APU!$A:$A,IF(ISNUMBER($C30),REPLACE(TEXT($C30,"0.0000"),5,0,"."),$C30),APU!$G:$G,"hh")/MAX(1,SUMPRODUCT(($C$15:$C$262=$C30)*($S$15:$S$262<>""))))} -> 7.98 | AC30: =IF($S30="","",IFERROR(VLOOKUP($AE30,APU!$V:$X,2,FALSE),"")) -> 20 | AD30: =IF(OR($S30="",$AC30="",N($AC30)=0),"",$S30/$AC30) -> 0.475 | AE30: =IF($C30="","",IF(ISNUMBER($C30),REPLACE(TEXT($C30,"0.0000"),5,0,"."),$C30)) -> 2.04.02 | AH30: =IF($S30="","",$AB30*N($AG30)) -> 0 | AI30: =IF($S30="","",$AE30&IF(TRIM($N30)="",""," | "&TRIM($N30))&IF(OR(TRIM($O30)="",TRIM($O30)="-"),""," | "&TRIM($O30))) -> 2.04.02
B31: 8.2.4 | C31: =+C30+0.0001 -> 2.0403 | D31: - | E31: - | F31: - | G31: Soporte metálico ASTM A36 para tuberías y tableros eléctricos | P31: =IF(TRIM($G31)="","",TRIM($G31)&IF(OR(TRIM($N31)="",TRIM($N31)="-"),""," - "&TRIM($N31))&IF(OR(TRIM($O31)="",TRIM($O31)="-"),""," - "&TRIM($O31))&IF(ISNUMBER(SEARCH("SUMINISTRO",$G31))," - "&$AK$13,IF(ISNUMBER(SEARCH("MONTAJE",$G31))," - "&$AK$12,""))) -> Soporte metálico ASTM A36 para tuberías y tableros eléctricos | Q31: En alcance | R31: {=IF($G31="","",IFERROR(VLOOKUP(LOOKUP(2,1/(($B$14:$B31<>"")*($C$14:$C31="")),$B$14:$B31),$AM$12:$AN$16,2,FALSE),""))} -> Civil | S31: =556.74+96.75 -> 653.49 | T31: kg | U31: =+APU!K169 -> 6.8543616 | V31: =U31*S31 -> 4479.2568 | AB31: {=IF($S31="","",SUMIFS(APU!$O:$O,APU!$A:$A,IF(ISNUMBER($C31),REPLACE(TEXT($C31,"0.0000"),5,0,"."),$C31),APU!$G:$G,"hh")/MAX(1,SUMPRODUCT(($C$15:$C$262=$C31)*($S$15:$S$262<>""))))} -> 43.914528 | AC31: =IF($S31="","",IFERROR(VLOOKUP($AE31,APU!$V:$X,2,FALSE),"")) -> 250 | AD31: =IF(OR($S31="",$AC31="",N($AC31)=0),"",$S31/$AC31) -> 2.61396 | AE31: =IF($C31="","",IF(ISNUMBER($C31),REPLACE(TEXT($C31,"0.0000"),5,0,"."),$C31)) -> 2.04.03 | AH31: =IF($S31="","",$AB31*N($AG31)) -> 0 | AI31: =IF($S31="","",$AE31&IF(TRIM($N31)="",""," | "&TRIM($N31))&IF(OR(TRIM($O31)="",TRIM($O31)="-"),""," | "&TRIM($O31))) -> 2.04.03
B32: 8.2.4 | C32: =+C31+0.0001 -> 2.0404 | D32: - | E32: - | F32: - | G32: Placa base para soportería de tuberías | P32: =IF(TRIM($G32)="","",TRIM($G32)&IF(OR(TRIM($N32)="",TRIM($N32)="-"),""," - "&TRIM($N32))&IF(OR(TRIM($O32)="",TRIM($O32)="-"),""," - "&TRIM($O32))&IF(ISNUMBER(SEARCH("SUMINISTRO",$G32))," - "&$AK$13,IF(ISNUMBER(SEARCH("MONTAJE",$G32))," - "&$AK$12,""))) -> Placa base para soportería de tuberías | Q32: En alcance | R32: {=IF($G32="","",IFERROR(VLOOKUP(LOOKUP(2,1/(($B$14:$B32<>"")*($C$14:$C32="")),$B$14:$B32),$AM$12:$AN$16,2,FALSE),""))} -> Civil | S32: =287.3+43.62 -> 330.92 | T32: kg | U32: =+APU!K190 -> 6.8543616 | V32: =U32*S32 -> 2268.2453 | AB32: {=IF($S32="","",SUMIFS(APU!$O:$O,APU!$A:$A,IF(ISNUMBER($C32),REPLACE(TEXT($C32,"0.0000"),5,0,"."),$C32),APU!$G:$G,"hh")/MAX(1,SUMPRODUCT(($C$15:$C$262=$C32)*($S$15:$S$262<>""))))} -> 22.237824 | AC32: =IF($S32="","",IFERROR(VLOOKUP($AE32,APU!$V:$X,2,FALSE),"")) -> 250 | AD32: =IF(OR($S32="",$AC32="",N($AC32)=0),"",$S32/$AC32) -> 1.32368 | AE32: =IF($C32="","",IF(ISNUMBER($C32),REPLACE(TEXT($C32,"0.0000"),5,0,"."),$C32)) -> 2.04.04 | AH32: =IF($S32="","",$AB32*N($AG32)) -> 0 | AI32: =IF($S32="","",$AE32&IF(TRIM($N32)="",""," | "&TRIM($N32))&IF(OR(TRIM($O32)="",TRIM($O32)="-"),""," | "&TRIM($O32))) -> 2.04.04
B33: 8.2.4 | C33: =+C32+0.0001 -> 2.0405 | D33: - | E33: - | F33: - | G33: Mortero de nivelacion de cemento e=25 mm, De acuerdo Especificación técnica 000.215.03600_0 | P33: =IF(TRIM($G33)="","",TRIM($G33)&IF(OR(TRIM($N33)="",TRIM($N33)="-"),""," - "&TRIM($N33))&IF(OR(TRIM($O33)="",TRIM($O33)="-"),""," - "&TRIM($O33))&IF(ISNUMBER(SEARCH("SUMINISTRO",$G33))," - "&$AK$13,IF(ISNUMBER(SEARCH("MONTAJE",$G33))," - "&$AK$12,""))) -> Mortero de nivelacion de cemento e=25 mm, De acuerdo Especificación técnica 000.215.03600_0 | Q33: En alcance | R33: {=IF($G33="","",IFERROR(VLOOKUP(LOOKUP(2,1/(($B$14:$B33<>"")*($C$14:$C33="")),$B$14:$B33),$AM$12:$AN$16,2,FALSE),""))} -> Civil | S33: =104.15+0.01125+0.004125 -> 104.16538 | T33: Lt | U33: =+APU!K211 -> 21.550511 | V33: =U33*S33 -> 2244.817 | AB33: {=IF($S33="","",SUMIFS(APU!$O:$O,APU!$A:$A,IF(ISNUMBER($C33),REPLACE(TEXT($C33,"0.0000"),5,0,"."),$C33),APU!$G:$G,"hh")/MAX(1,SUMPRODUCT(($C$15:$C$262=$C33)*($S$15:$S$262<>""))))} -> 174.99783 | AC33: =IF($S33="","",IFERROR(VLOOKUP($AE33,APU!$V:$X,2,FALSE),"")) -> 10 | AD33: =IF(OR($S33="",$AC33="",N($AC33)=0),"",$S33/$AC33) -> 10.416538 | AE33: =IF($C33="","",IF(ISNUMBER($C33),REPLACE(TEXT($C33,"0.0000"),5,0,"."),$C33)) -> 2.04.05 | AH33: =IF($S33="","",$AB33*N($AG33)) -> 0 | AI33: =IF($S33="","",$AE33&IF(TRIM($N33)="",""," | "&TRIM($N33))&IF(OR(TRIM($O33)="",TRIM($O33)="-"),""," | "&TRIM($O33))) -> 2.04.05
B34: 8.2.4 | C34: =+C33+0.0001 -> 2.0406 | D34: - | E34: - | F34: - | G34: Perno de expansión 1/2"x3" | P34: =IF(TRIM($G34)="","",TRIM($G34)&IF(OR(TRIM($N34)="",TRIM($N34)="-"),""," - "&TRIM($N34))&IF(OR(TRIM($O34)="",TRIM($O34)="-"),""," - "&TRIM($O34))&IF(ISNUMBER(SEARCH("SUMINISTRO",$G34))," - "&$AK$13,IF(ISNUMBER(SEARCH("MONTAJE",$G34))," - "&$AK$12,""))) -> Perno de expansión 1/2"x3" | Q34: En alcance | R34: {=IF($G34="","",IFERROR(VLOOKUP(LOOKUP(2,1/(($B$14:$B34<>"")*($C$14:$C34="")),$B$14:$B34),$AM$12:$AN$16,2,FALSE),""))} -> Civil | S34: 102 | T34: UND | U34: =+APU!K229 -> 11.860789 | V34: =U34*S34 -> 1209.8004 | AB34: {=IF($S34="","",SUMIFS(APU!$O:$O,APU!$A:$A,IF(ISNUMBER($C34),REPLACE(TEXT($C34,"0.0000"),5,0,"."),$C34),APU!$G:$G,"hh")/MAX(1,SUMPRODUCT(($C$15:$C$262=$C34)*($S$15:$S$262<>""))))} -> 114.24 | AC34: =IF($S34="","",IFERROR(VLOOKUP($AE34,APU!$V:$X,2,FALSE),"")) -> 15 | AD34: =IF(OR($S34="",$AC34="",N($AC34)=0),"",$S34/$AC34) -> 6.8 | AE34: =IF($C34="","",IF(ISNUMBER($C34),REPLACE(TEXT($C34,"0.0000"),5,0,"."),$C34)) -> 2.04.06 | AH34: =IF($S34="","",$AB34*N($AG34)) -> 0 | AI34: =IF($S34="","",$AE34&IF(TRIM($N34)="",""," | "&TRIM($N34))&IF(OR(TRIM($O34)="",TRIM($O34)="-"),""," | "&TRIM($O34))) -> 2.04.06
B35: 8.2.4 | C35: =+C34+0.0001 -> 2.0407 | D35: - | E35: - | F35: - | G35: Perno de expansión 5/8"x3" | P35: =IF(TRIM($G35)="","",TRIM($G35)&IF(OR(TRIM($N35)="",TRIM($N35)="-"),""," - "&TRIM($N35))&IF(OR(TRIM($O35)="",TRIM($O35)="-"),""," - "&TRIM($O35))&IF(ISNUMBER(SEARCH("SUMINISTRO",$G35))," - "&$AK$13,IF(ISNUMBER(SEARCH("MONTAJE",$G35))," - "&$AK$12,""))) -> Perno de expansión 5/8"x3" | Q35: En alcance | R35: {=IF($G35="","",IFERROR(VLOOKUP(LOOKUP(2,1/(($B$14:$B35<>"")*($C$14:$C35="")),$B$14:$B35),$AM$12:$AN$16,2,FALSE),""))} -> Civil | S35: 26 | T35: UND | U35: =+APU!K246 -> 13.860789 | V35: =U35*S35 -> 360.3805 | AB35: {=IF($S35="","",SUMIFS(APU!$O:$O,APU!$A:$A,IF(ISNUMBER($C35),REPLACE(TEXT($C35,"0.0000"),5,0,"."),$C35),APU!$G:$G,"hh")/MAX(1,SUMPRODUCT(($C$15:$C$262=$C35)*($S$15:$S$262<>""))))} -> 29.12 | AC35: =IF($S35="","",IFERROR(VLOOKUP($AE35,APU!$V:$X,2,FALSE),"")) -> 15 | AD35: =IF(OR($S35="",$AC35="",N($AC35)=0),"",$S35/$AC35) -> 1.7333333 | AE35: =IF($C35="","",IF(ISNUMBER($C35),REPLACE(TEXT($C35,"0.0000"),5,0,"."),$C35)) -> 2.04.07 | AH35: =IF($S35="","",$AB35*N($AG35)) -> 0 | AI35: =IF($S35="","",$AE35&IF(TRIM($N35)="",""," | "&TRIM($N35))&IF(OR(TRIM($O35)="",TRIM($O35)="-"),""," | "&TRIM($O35))) -> 2.04.07
B36: 8.2.4 | C36: =+C35+0.0001 -> 2.0408 | D36: - | E36: - | F36: - | G36: Perno de expansión 3/4"x5" | P36: =IF(TRIM($G36)="","",TRIM($G36)&IF(OR(TRIM($N36)="",TRIM($N36)="-"),""," - "&TRIM($N36))&IF(OR(TRIM($O36)="",TRIM($O36)="-"),""," - "&TRIM($O36))&IF(ISNUMBER(SEARCH("SUMINISTRO",$G36))," - "&$AK$13,IF(ISNUMBER(SEARCH("MONTAJE",$G36))," - "&$AK$12,""))) -> Perno de expansión 3/4"x5" | Q36: En alcance | R36: {=IF($G36="","",IFERROR(VLOOKUP(LOOKUP(2,1/(($B$14:$B36<>"")*($C$14:$C36="")),$B$14:$B36),$AM$12:$AN$16,2,FALSE),""))} -> Civil | S36: 12 | T36: UND | U36: =+APU!K263 -> 14.432217 | V36: =U36*S36 -> 173.18661 | AB36: {=IF($S36="","",SUMIFS(APU!$O:$O,APU!$A:$A,IF(ISNUMBER($C36),REPLACE(TEXT($C36,"0.0000"),5,0,"."),$C36),APU!$G:$G,"hh")/MAX(1,SUMPRODUCT(($C$15:$C$262=$C36)*($S$15:$S$262<>""))))} -> 13.44 | AC36: =IF($S36="","",IFERROR(VLOOKUP($AE36,APU!$V:$X,2,FALSE),"")) -> 15 | AD36: =IF(OR($S36="",$AC36="",N($AC36)=0),"",$S36/$AC36) -> 0.8 | AE36: =IF($C36="","",IF(ISNUMBER($C36),REPLACE(TEXT($C36,"0.0000"),5,0,"."),$C36)) -> 2.04.08 | AH36: =IF($S36="","",$AB36*N($AG36)) -> 0 | AI36: =IF($S36="","",$AE36&IF(TRIM($N36)="",""," | "&TRIM($N36))&IF(OR(TRIM($O36)="",TRIM($O36)="-"),""," | "&TRIM($O36))) -> 2.04.08
B37: 8.2.4 | C37: =+C36+0.0001 -> 2.0409 | D37: - | E37: - | F37: - | G37: Pernos de anclaje embebido ASTM A36 Ø1/2" de 180 mm de los pedestales | P37: =IF(TRIM($G37)="","",TRIM($G37)&IF(OR(TRIM($N37)="",TRIM($N37)="-"),""," - "&TRIM($N37))&IF(OR(TRIM($O37)="",TRIM($O37)="-"),""," - "&TRIM($O37))&IF(ISNUMBER(SEARCH("SUMINISTRO",$G37))," - "&$AK$13,IF(ISNUMBER(SEARCH("MONTAJE",$G37))," - "&$AK$12,""))) -> Pernos de anclaje embebido ASTM A36 Ø1/2" de 180 mm de los pedestales | Q37: En alcance | R37: {=IF($G37="","",IFERROR(VLOOKUP(LOOKUP(2,1/(($B$14:$B37<>"")*($C$14:$C37="")),$B$14:$B37),$AM$12:$AN$16,2,FALSE),""))} -> Civil | S37: 28 | T37: UND | U37: =+APU!K280 -> 29.759754 | V37: =U37*S37 -> 833.27312 | AB37: {=IF($S37="","",SUMIFS(APU!$O:$O,APU!$A:$A,IF(ISNUMBER($C37),REPLACE(TEXT($C37,"0.0000"),5,0,"."),$C37),APU!$G:$G,"hh")/MAX(1,SUMPRODUCT(($C$15:$C$262=$C37)*($S$15:$S$262<>""))))} -> 47.04 | AC37: =IF($S37="","",IFERROR(VLOOKUP($AE37,APU!$V:$X,2,FALSE),"")) -> 10 | AD37: =IF(OR($S37="",$AC37="",N($AC37)=0),"",$S37/$AC37) -> 2.8 | AE37: =IF($C37="","",IF(ISNUMBER($C37),REPLACE(TEXT($C37,"0.0000"),5,0,"."),$C37)) -> 2.04.09 | AH37: =IF($S37="","",$AB37*N($AG37)) -> 0 | AI37: =IF($S37="","",$AE37&IF(TRIM($N37)="",""," | "&TRIM($N37))&IF(OR(TRIM($O37)="",TRIM($O37)="-"),""," | "&TRIM($O37))) -> 2.04.09
B38: 8.2.4 | C38: =+C37+0.0001 -> 2.041 | D38: - | E38: - | F38: - | G38: Picado, escarificado y limpieza sobre losa existente | P38: =IF(TRIM($G38)="","",TRIM($G38)&IF(OR(TRIM($N38)="",TRIM($N38)="-"),""," - "&TRIM($N38))&IF(OR(TRIM($O38)="",TRIM($O38)="-"),""," - "&TRIM($O38))&IF(ISNUMBER(SEARCH("SUMINISTRO",$G38))," - "&$AK$13,IF(ISNUMBER(SEARCH("MONTAJE",$G38))," - "&$AK$12,""))) -> Picado, escarificado y limpieza sobre losa existente | Q38: En alcance | R38: {=IF($G38="","",IFERROR(VLOOKUP(LOOKUP(2,1/(($B$14:$B38<>"")*($C$14:$C38="")),$B$14:$B38),$AM$12:$AN$16,2,FALSE),""))} -> Civil | S38: 0.615 | T38: m2 | U38: =+APU!K296 -> 13.08936 | V38: =U38*S38 -> 8.0499564 | AB38: {=IF($S38="","",SUMIFS(APU!$O:$O,APU!$A:$A,IF(ISNUMBER($C38),REPLACE(TEXT($C38,"0.0000"),5,0,"."),$C38),APU!$G:$G,"hh")/MAX(1,SUMPRODUCT(($C$15:$C$262=$C38)*($S$15:$S$262<>""))))} -> 0.6888 | AC38: =IF($S38="","",IFERROR(VLOOKUP($AE38,APU!$V:$X,2,FALSE),"")) -> 15 | AD38: =IF(OR($S38="",$AC38="",N($AC38)=0),"",$S38/$AC38) -> 0.041 | AE38: =IF($C38="","",IF(ISNUMBER($C38),REPLACE(TEXT($C38,"0.0000"),5,0,"."),$C38)) -> 2.04.10 | AH38: =IF($S38="","",$AB38*N($AG38)) -> 0 | AI38: =IF($S38="","",$AE38&IF(TRIM($N38)="",""," | "&TRIM($N38))&IF(OR(TRIM($O38)="",TRIM($O38)="-"),""," | "&TRIM($O38))) -> 2.04.10
B39: MECÁNICA - TUBERIAS | AB39: {=IF($S39="","",SUMIFS(APU!$O:$O,APU!$A:$A,IF(ISNUMBER($C39),REPLACE(TEXT($C39,"0.0000"),5,0,"."),$C39),APU!$G:$G,"hh")/MAX(1,SUMPRODUCT(($C$15:$C$262=$C39)*($S$15:$S$262<>""))))} | AC39: =IF($S39="","",IFERROR(VLOOKUP($AE39,APU!$V:$X,2,FALSE),"")) | AD39: =IF(OR($S39="",$AC39="",N($AC39)=0),"",$S39/$AC39) | AE39: =IF($C39="","",IF(ISNUMBER($C39),REPLACE(TEXT($C39,"0.0000"),5,0,"."),$C39)) | AH39: =IF($S39="","",$AB39*N($AG39)) | AI39: =IF($S39="","",$AE39&IF(TRIM($N39)="",""," | "&TRIM($N39))&IF(OR(TRIM($O39)="",TRIM($O39)="-"),""," | "&TRIM($O39)))
B40: 8.3.1 | C40: 3.01 | D40: - | E40: - | F40: - | G40: GENERALES | P40: =IF(TRIM($G40)="","",TRIM($G40)&IF(OR(TRIM($N40)="",TRIM($N40)="-"),""," - "&TRIM($N40))&IF(OR(TRIM($O40)="",TRIM($O40)="-"),""," - "&TRIM($O40))&IF(ISNUMBER(SEARCH("SUMINISTRO",$G40))," - "&$AK$13,IF(ISNUMBER(SEARCH("MONTAJE",$G40))," - "&$AK$12,""))) -> GENERALES | Q40: En alcance | R40: {=IF($G40="","",IFERROR(VLOOKUP(LOOKUP(2,1/(($B$14:$B40<>"")*($C$14:$C40="")),$B$14:$B40),$AM$12:$AN$16,2,FALSE),""))} -> Mecanica | AB40: {=IF($S40="","",SUMIFS(APU!$O:$O,APU!$A:$A,IF(ISNUMBER($C40),REPLACE(TEXT($C40,"0.0000"),5,0,"."),$C40),APU!$G:$G,"hh")/MAX(1,SUMPRODUCT(($C$15:$C$262=$C40)*($S$15:$S$262<>""))))} | AC40: =IF($S40="","",IFERROR(VLOOKUP($AE40,APU!$V:$X,2,FALSE),"")) | AD40: =IF(OR($S40="",$AC40="",N($AC40)=0),"",$S40/$AC40) | AE40: =IF($C40="","",IF(ISNUMBER($C40),REPLACE(TEXT($C40,"0.0000"),5,0,"."),$C40)) -> 3.01.00 | AH40: =IF($S40="","",$AB40*N($AG40)) | AI40: =IF($S40="","",$AE40&IF(TRIM($N40)="",""," | "&TRIM($N40))&IF(OR(TRIM($O40)="",TRIM($O40)="-"),""," | "&TRIM($O40)))
B41: 8.3.1 | C41: 3.01.01 | D41: - | E41: - | F41: - | G41: Etiquetado de tuberías | N41: - | O41: - | P41: =IF(TRIM($G41)="","",TRIM($G41)&IF(OR(TRIM($N41)="",TRIM($N41)="-"),""," - "&TRIM($N41))&IF(OR(TRIM($O41)="",TRIM($O41)="-"),""," - "&TRIM($O41))&IF(ISNUMBER(SEARCH("SUMINISTRO",$G41))," - "&$AK$13,IF(ISNUMBER(SEARCH("MONTAJE",$G41))," - "&$AK$12,""))) -> Etiquetado de tuberías | Q41: En alcance | R41: {=IF($G41="","",IFERROR(VLOOKUP(LOOKUP(2,1/(($B$14:$B41<>"")*($C$14:$C41="")),$B$14:$B41),$AM$12:$AN$16,2,FALSE),""))} -> Mecanica | S41: 1 | T41: Glb. | U41: =+APU!K312 -> 2447.404 | V41: =U41*S41 -> 2447.404 | AB41: {=IF($S41="","",SUMIFS(APU!$O:$O,APU!$A:$A,IF(ISNUMBER($C41),REPLACE(TEXT($C41,"0.0000"),5,0,"."),$C41),APU!$G:$G,"hh")/MAX(1,SUMPRODUCT(($C$15:$C$262=$C41)*($S$15:$S$262<>""))))} -> 168 | AC41: =IF($S41="","",IFERROR(VLOOKUP($AE41,APU!$V:$X,2,FALSE),"")) -> 0.1 | AD41: =IF(OR($S41="",$AC41="",N($AC41)=0),"",$S41/$AC41) -> 10 | AE41: =IF($C41="","",IF(ISNUMBER($C41),REPLACE(TEXT($C41,"0.0000"),5,0,"."),$C41)) -> 3.01.01 | AH41: =IF($S41="","",$AB41*N($AG41)) -> 0 | AI41: =IF($S41="","",$AE41&IF(TRIM($N41)="",""," | "&TRIM($N41))&IF(OR(TRIM($O41)="",TRIM($O41)="-"),""," | "&TRIM($O41))) -> 3.01.01 | -
...

Sheet APU
O1: hh | Q1: QPS S | R1: APU suma P | S1: Dif | V1: Cód. partida (norm.) | W1: Rendimiento / DIA | X1: Unidad rendimiento
C2: Partida | D2: =QPS!C16 -> 1.0101 | E2: =QPS!G16 -> Movilización y desmovilización | Q2: =QPS!V16 -> 6797.26 | R2: =SUM(P2:P14) -> 6797.26 | S2: =Q2-R2 -> 0 | V2: =IF($D2="","",IF(ISNUMBER($D2),REPLACE(TEXT($D2,"0.0000"),5,0,"."),TRIM($D2))) -> 1.01.01 | W2: =$F3 -> 0.2 | X2: =$D3 -> glb/DIA
C3: Rendimiento | D3: glb/DIA | E3: MO. | F3: 0.2 | G3: EQ. | H3: =F3 -> 0.2 | J3: Costo unitario directo por : glb | K3: =+K8+K13 -> 6797.26 | V3: =IF($D15="","",IF(ISNUMBER($D15),REPLACE(TEXT($D15,"0.0000"),5,0,"."),TRIM($D15))) -> 1.01.02 | W3: =$F16 -> 0.5 | X3: =$D16 -> glb/DIA
C4: Código | D4: Descripción Recurso | G4: Unidad | H4: Cuadrilla | I4: Cantidad | J4: Precio U$ | K4: Parcial U$ | V4: =IF($D32="","",IF(ISNUMBER($D32),REPLACE(TEXT($D32,"0.0000"),5,0,"."),TRIM($D32))) -> 1.01.03 | W4: =$F33 -> 1 | X4: =$D33 -> glb/DIA
D5: Mano de Obra | V5: =IF($D40="","",IF(ISNUMBER($D40),REPLACE(TEXT($D40,"0.0000"),5,0,"."),TRIM($D40))) -> 2.01.01 | W5: =$F41 -> 0.4 | X5: =$D41 -> m3/DIA
A6: 1.01.01 | B6: Mano de Obra | C6: 0101010002 | D6: CAPATAZ | G6: hh | H6: 1 | I6: =H6*8/$F$3 -> 40 | J6: 10.51 | K6: =I6*J6 -> 420.4 | M6: 1 | N6: Glb. | O6: =I6*M6 -> 40 | P6: =O6*J6 -> 420.4 | V6: =IF($D56="","",IF(ISNUMBER($D56),REPLACE(TEXT($D56,"0.0000"),5,0,"."),TRIM($D56))) -> 2.02.01 | W6: =$F57 -> 15 | X6: =$D57 -> m3/DIA
A7: 1.01.01 | B7: Mano de Obra | C7: 01010300030005 | D7: AYUDANTE | G7: hh | H7: 4 | I7: =H7*8/$F$3 -> 160 | J7: 6.88 | K7: =I7*J7 -> 1100.8 | M7: 1 | N7: Glb. | O7: =I7*M7 -> 160 | P7: =O7*J7 -> 1100.8 | V7: =IF($D74="","",IF(ISNUMBER($D74),REPLACE(TEXT($D74,"0.0000"),5,0,"."),TRIM($D74))) -> 2.03.01 | W7: =$F75 -> 15 | X7: =$D75 -> m3/DIA
K8: =SUM(K6:K7) -> 1521.2 | V8: =IF($D95="","",IF(ISNUMBER($D95),REPLACE(TEXT($D95,"0.0000"),5,0,"."),TRIM($D95))) -> 2.03.02 | W8: =$F96 -> 18 | X8: =$D96 -> m2/DIA
D9: Equipos | V9: =IF($D116="","",IF(ISNUMBER($D116),REPLACE(TEXT($D116,"0.0000"),5,0,"."),TRIM($D116))) -> 2.03.03 | W9: =$F117 -> 250 | X9: =$D117 -> kg/DIA
A10: 1.01.01 | B10: Equipos | C10: 0301010006 | D10: HERRAMIENTAS MANUALES | G10: %mo | I10: 5 | J10: =K8 -> 1521.2 | K10: =I10*J10/100 -> 76.06 | M10: 1 | N10: Glb. | O10: =I10*M10 -> 5 | P10: =O10*J10/100 -> 76.06 | V10: =IF($D134="","",IF(ISNUMBER($D134),REPLACE(TEXT($D134,"0.0000"),5,0,"."),TRIM($D134))) -> 2.04.01 | W10: =$F135 -> 20 | X10: =$D135 -> und/DIA
A11: 1.01.01 | B11: Equipos | D11: CAMION GRUA DE 12TN | G11: hm | H11: 1 | I11: =H11*8/$H$3 -> 40 | J11: 95 | K11: =I11*J11 -> 3800 | M11: 1 | N11: Glb. | O11: =I11*M11 -> 40 | P11: =O11*J11 -> 3800 | V11: =IF($D151="","",IF(ISNUMBER($D151),REPLACE(TEXT($D151,"0.0000"),5,0,"."),TRIM($D151))) -> 2.04.02 | W11: =$F152 -> 20 | X11: =$D152 -> m/DIA
A12: 1.01.01 | B12: Equipos | D12: CAMION BARANDA (4TN) | G12: hm | H12: 1 | I12: =H12*8/$H$3 -> 40 | J12: 35 | K12: =I12*J12 -> 1400 | M12: 1 | N12: Glb. | O12: =I12*M12 -> 40 | P12: =O12*J12 -> 1400 | V12: =IF($D168="","",IF(ISNUMBER($D168),REPLACE(TEXT($D168,"0.0000"),5,0,"."),TRIM($D168))) -> 2.04.03 | W12: =$F169 -> 250 | X12: =$D169 -> kg/DIA
K13: =SUM(K10:K12) -> 5276.06 | V13: =IF($D189="","",IF(ISNUMBER($D189),REPLACE(TEXT($D189,"0.0000"),5,0,"."),TRIM($D189))) -> 2.04.04 | W13: =$F190 -> 250 | X13: =$D190 -> kg/DIA
V14: =IF($D210="","",IF(ISNUMBER($D210),REPLACE(TEXT($D210,"0.0000"),5,0,"."),TRIM($D210))) -> 2.04.05 | W14: =$F211 -> 10 | X14: =$D211 -> l/DIA
C15: Partida | D15: =QPS!C17 -> 1.0102 | E15: =QPS!G17 -> Trazo y replanteo (preliminar y durante la obra) | Q15: =QPS!V17 -> 518.25029 | R15: =SUM(P15:P31) -> 518.25029 | S15: =Q15-R15 -> 0 | V15: =IF($D228="","",IF(ISNUMBER($D228),REPLACE(TEXT($D228,"0.0000"),5,0,"."),TRIM($D228))) -> 2.04.06 | W15: =$F229 -> 15 | X15: =$D229 -> und/DIA
C16: Rendimiento | D16: glb/DIA | E16: MO. | F16: 0.5 | G16: EQ. | H16: =F16 -> 0.5 | J16: Costo unitario directo por : glb | K16: =+K21+K26+K30 -> 518.25029 | V16: =IF($D245="","",IF(ISNUMBER($D245),REPLACE(TEXT($D245,"0.0000"),5,0,"."),TRIM($D245))) -> 2.04.07 | W16: =$F246 -> 15 | X16: =$D246 -> und/DIA
C17: Código | D17: Descripción Recurso | G17: Unidad | H17: Cuadrilla | I17: Cantidad | J17: Precio U$ | K17: Parcial U$ | V17: =IF($D262="","",IF(ISNUMBER($D262),REPLACE(TEXT($D262,"0.0000"),5,0,"."),TRIM($D262))) -> 2.04.08 | W17: =$F263 -> 15 | X17: =$D263 -> und/DIA
D18: Mano de Obra | V18: =IF($D279="","",IF(ISNUMBER($D279),REPLACE(TEXT($D279,"0.0000"),5,0,"."),TRIM($D279))) -> 2.04.09 | W18: =$F280 -> 10 | X18: =$D280 -> und/DIA
A19: 1.01.02 | B19: Mano de Obra | C19: 0101010002 | D19: CAPATAZ | G19: hh | H19: 1 | I19: =H19*8/$F$16 -> 16 | J19: 10.51 | K19: =I19*J19 -> 168.16 | M19: 1 | N19: Glb. | O19: =I19*M19 -> 16 | P19: =O19*J19 -> 168.16 | V19: =IF($D295="","",IF(ISNUMBER($D295),REPLACE(TEXT($D295,"0.0000"),5,0,"."),TRIM($D295))) -> 2.04.10 | W19: =$F296 -> 15 | X19: =$D296 -> m2/DIA
A20: 1.01.02 | B20: Mano de Obra | C20: 01010300030005 | D20: AYUDANTE | G20: hh | H20: 2 | I20: =H20*8/$F$16 -> 32 | J20: 6.88 | K20: =I20*J20 -> 220.16 | M20: 1 | N20: Glb. | O20: =I20*M20 -> 32 | P20: =O20*J20 -> 220.16 | V20: =IF($D311="","",IF(ISNUMBER($D311),REPLACE(TEXT($D311,"0.0000"),5,0,"."),TRIM($D311))) -> 3.01.01 | W20: =$F312 -> 0.1 | X20: =$D312 -> glb/DIA
K21: =SUM(K19:K20) -> 388.32 | V21: =IF($D326="","",IF(ISNUMBER($D326),REPLACE(TEXT($D326,"0.0000"),5,0,"."),TRIM($D326))) -> 3.01.02 | W21: =$F327 -> 0.5 | X21: =$D327 -> glb/DIA
D22: Materiales | V22: =IF($D342="","",IF(ISNUMBER($D342),REPLACE(TEXT($D342,"0.0000"),5,0,"."),TRIM($D342))) -> 3.01.03 | W22: =$F343 -> 0.25 | X22: =$D343 -> glb/DIA
A23: 1.01.02 | B23: Materiales | D23: YESO | G23: bolsa | I23: 2 | J23: =17.9/3.5 -> 5.1142857 | K23: =I23*J23 -> 10.228571 | M23: 1 | N23: Glb. | O23: =I23*M23 -> 2 | P23: =O23*J23 -> 10.228571 | V23: =IF($D358="","",IF(ISNUMBER($D358),REPLACE(TEXT($D358,"0.0000"),5,0,"."),TRIM($D358))) -> 3.02.01 | W23: =$F359 -> 0.5 | X23: =$D359 -> und/DIA
A24: 1.01.02 | B24: Materiales | D24: ESTACAS | G24: und | I24: 50 | J24: =4.35/3.5 -> 1.2428571 | K24: =I24*J24 -> 62.142857 | M24: 1 | N24: Glb. | O24: =I24*M24 -> 50 | P24: =O24*J24 -> 62.142857 | V24: =IF($D374="","",IF(ISNUMBER($D374),REPLACE(TEXT($D374,"0.0000"),5,0,"."),TRIM($D374))) -> 3.03.01 | W24: =$F375 -> 0.15 | X24: =$D375 -> glb/DIA
A25: 1.01.02 | B25: Materiales | D25: PINTURA AEROSOL | G25: und | I25: 5 | J25: =16.7/3.5 -> 4.7714286 | K25: =I25*J25 -> 23.857143 | M25: 1 | N25: Glb. | O25: =I25*M25 -> 5 | P25: =O25*J25 -> 23.857143 | V25: =IF($D391="","",IF(ISNUMBER($D391),REPLACE(TEXT($D391,"0.0000"),5,0,"."),TRIM($D391))) -> 3.04.01 | W25: =$F392 -> 1 | X25: =$D392 -> und/DIA
K26: =SUM(K23:K25) -> 96.228571 | V26: =IF($D408="","",IF(ISNUMBER($D408),REPLACE(TEXT($D408,"0.0000"),5,0,"."),TRIM($D408))) -> 3.04.02 | W26: =$F409 -> 1 | X26: =$D409 -> und/DIA
D27: Equipos | V27: =IF($D425="","",IF(ISNUMBER($D425),REPLACE(TEXT($D425,"0.0000"),5,0,"."),TRIM($D425))) -> 3.04.03 | W27: =$F426 -> 1 | X27: =$D426 -> und/DIA
A28: 1.01.02 | B28: Equipos | C28: 0301010006 | D28: HERRAMIENTAS MANUALES | G28: %mo | I28: 5 | J28: =K21 -> 388.32 | K28: =I28*J28/100 -> 19.416 | M28: 1 | N28: Glb. | O28: =I28*M28 -> 5 | P28: =O28*J28/100 -> 19.416 | V28: =IF($D442="","",IF(ISNUMBER($D442),REPLACE(TEXT($D442,"0.0000"),5,0,"."),TRIM($D442))) -> 3.04.04 | W28: =$F443 -> 1 | X28: =$D443 -> und/DIA
A29: 1.01.02 | B29: Equipos | D29: NIVEL DE INGENIERO | G29: hm | H29: 1 | I29: =H29*8/H16 -> 16 | J29: =25/3.5/8 -> 0.89285714 | K29: =I29*J29 -> 14.285714 | M29: 1 | N29: Glb. | O29: =I29*M29 -> 16 | P29: =O29*J29 -> 14.285714 | V29: =IF($D459="","",IF(ISNUMBER($D459),REPLACE(TEXT($D459,"0.0000"),5,0,"."),TRIM($D459))) -> 3.04.05 | W29: =$F460 -> 1 | X29: =$D460 -> und/DIA
K30: =SUM(K28:K29) -> 33.701714 | V30: =IF($D477="","",IF(ISNUMBER($D477),REPLACE(TEXT($D477,"0.0000"),5,0,"."),TRIM($D477))) -> 3.05.01 | W30: =$F478 -> 1 | X30: =$D478 -> und/DIA
V31: =IF($D494="","",IF(ISNUMBER($D494),REPLACE(TEXT($D494,"0.0000"),5,0,"."),TRIM($D494))) -> 3.05.02 | W31: =$F495 -> 1 | X31: =$D495 -> und/DIA
C32: Partida | D32: =QPS!C18 -> 1.0103 | E32: =QPS!G18 -> Limpieza del área de trabajo | Q32: =QPS!V18 -> 236.976 | R32: =SUM(P32:P39) -> 236.976 | S32: =Q32-R32 -> 0 | V32: =IF($D511="","",IF(ISNUMBER($D511),REPLACE(TEXT($D511,"0.0000"),5,0,"."),TRIM($D511))) -> 3.06.01 | W32: =$F512 -> 15 | X32: =$D512 -> m/DIA
C33: Rendimiento | D33: glb/DIA | E33: MO. | F33: 1 | G33: EQ. | H33: =F33 -> 1 | J33: Costo unitario directo por : glb | K33: =+K38 -> 236.976 | V33: =IF($D532="","",IF(ISNUMBER($D532),REPLACE(TEXT($D532,"0.0000"),5,0,"."),TRIM($D532))) -> 3.06.02 | W33: =$F533 -> 8 | X33: =$D533 -> m/DIA
C34: Código | D34: Descripción Recurso | G34: Unidad | H34: Cuadrilla | I34: Cantidad | J34: Precio U$ | K34: Parcial U$ | V34: =IF($D553="","",IF(ISNUMBER($D553),REPLACE(TEXT($D553,"0.0000"),5,0,"."),TRIM($D553))) -> 3.06.03 | W34: =$F554 -> 4 | X34: =$D554 -> und/DIA
D35: Mano de Obra | V35: =IF($D569="","",IF(ISNUMBER($D569),REPLACE(TEXT($D569,"0.0000"),5,0,"."),TRIM($D569))) -> 3.06.04 | W35: =$F570 -> 4 | X35: =$D570 -> und/DIA
A36: 1.01.03 | B36: Mano de Obra | C36: 0101010002 | D36: CAPATAZ | G36: hh | H36: 0.2 | I36: =H36*8/$F$33 -> 1.6 | J36: 10.51 | K36: =I36*J36 -> 16.816 | M36: 1 | N36: Glb. | O36: =I36*M36 -> 1.6 | P36: =O36*J36 -> 16.816 | V36: =IF($D585="","",IF(ISNUMBER($D585),REPLACE(TEXT($D585,"0.0000"),5,0,"."),TRIM($D585))) -> 3.06.05 | W36: =$F586 -> 6 | X36: =$D586 -> und/DIA
A37: 1.01.03 | B37: Mano de Obra | C37: 01010300030005 | D37: AYUDANTE | G37: hh | H37: 4 | I37: =H37*8/$F$33 -> 32 | J37: 6.88 | K37: =I37*J37 -> 220.16 | M37: 1 | N37: Glb. | O37: =I37*M37 -> 32 | P37: =O37*J37 -> 220.16 | V37: =IF($D601="","",IF(ISNUMBER($D601),REPLACE(TEXT($D601,"0.0000"),5,0,"."),TRIM($D601))) -> 3.06.06 | W37: =$F602 -> 6 | X37: =$D602 -> und/DIA
K38: =SUM(K36:K37) -> 236.976 | V38: =IF($D621="","",IF(ISNUMBER($D621),REPLACE(TEXT($D621,"0.0000"),5,0,"."),TRIM($D621))) -> 3.06.07 | W38: =$F622 -> 6 | X38: =$D622 -> und/DIA
V39: =IF($D641="","",IF(ISNUMBER($D641),REPLACE(TEXT($D641,"0.0000"),5,0,"."),TRIM($D641))) -> 3.06.08 | W39: =$F642 -> 6 | X39: =$D642 -> und/DIA
C40: Partida | D40: =QPS!C21 -> 2.0101 | E40: =QPS!G21 -> Demolición de bases e = 50 cm | Q40: =QPS!V21 -> 538.68928 | R40: =SUM(P40:P55) -> 538.68928 | S40: =Q40-R40 -> 0 | V40: =IF($D661="","",IF(ISNUMBER($D661),REPLACE(TEXT($D661,"0.0000"),5,0,"."),TRIM($D661))) -> 3.06.09 | W40: =$F662 -> 6 | X40: =$D662 -> und/DIA
...

Sheet GG
B2: GASTOS GENERALES
B5: PROYECTO : | C5: "Reposición del Sistema de Floculante"
B7: FECHA: | C7: 45965
J9: COSTO DIRECTO DE OBRA: | K9: =+QPS!V263 -> 210563.04
B11: RECURSO | D11: UNIDAD | E11: CANT. | F11: PERIODO | G11: CANT PERIOD | H11: COSTO/UNIDAD $ | I11: %INC. | J11: COSTO PARCIAL $ | K11: TOTAL
B14: 01 PERSONAL ADMINISTRATIVO Y AUXILIAR
C15: GERENTE GENERAL | D15: PER | E15: 1 | F15: MES | G15: 3.5 | H15: 5000 | I15: 0.1 | J15: =I15*E15*H15 -> 500 | K15: =J15*G15 -> 1750
C16: ADMINISTRADOR | D16: PER | E16: 1 | F16: MES | G16: 3.5 | H16: 2000 | I16: 0.2 | J16: =I16*E16*H16 -> 400 | K16: =J16*G16 -> 1400
C17: RRHH | D17: PER | E17: 1 | F17: MES | G17: 3.5 | H17: 2000 | I17: 0.2 | J17: =I17*E17*H17 -> 400 | K17: =J17*G17 -> 1400
C18: COMUNICACIONES | D18: UND | E18: 3 | F18: MES | G18: 3.5 | H18: 50 | I18: 0.25 | J18: =I18*E18*H18 -> 37.5 | K18: =J18*G18 -> 131.25
C19: MATERIAL DE ESCRITORIO | D19: GLB | E19: 1 | F19: MES | G19: 3.5 | H19: 150 | I19: 0.25 | J19: =I19*E19*H19 -> 37.5 | K19: =J19*G19 -> 131.25
C20: OFICINA | D20: UND | E20: 1 | F20: MES | G20: 3.5 | H20: 250 | I20: 0.25 | J20: =I20*E20*H20 -> 62.5 | K20: =J20*G20 -> 218.75
J21: TOTAL 01 | K21: =SUM(K15:K20) -> 5031.25
B22: 02 LOGISTICA
C23: COMPRADOR | D23: PER | E23: 1 | F23: MES | G23: 3.5 | H23: 2200 | I23: 0.25 | J23: =I23*E23*H23 -> 550 | K23: =J23*G23 -> 1925
C24: ALMACENERO CENTRAL | D24: PER | E24: 1 | F24: MES | G24: 3.5 | H24: 1200 | I24: 0.35 | J24: =I24*E24*H24 -> 420 | K24: =J24*G24 -> 1470
C25: ALMACENERO SATELITAL | D25: PER | E25: 1 | F25: MES | G25: 3.5 | H25: 950 | I25: 1 | J25: =I25*E25*H25 -> 950 | K25: =J25*G25 -> 3325
C26: COMUNICACIONES | D26: UND | E26: 2 | F26: MES | G26: 3.5 | H26: 50 | I26: 0.2 | J26: =I26*E26*H26 -> 20 | K26: =J26*G26 -> 70
J27: TOTAL 02 | K27: =SUM(K23:K26) -> 6790
B28: 03 PRODUCCION
C29: JEFE DE OPERACIONES | D29: PER | E29: 1 | F29: MES | G29: 3.5 | H29: 4000 | I29: 0.3 | J29: =I29*E29*H29 -> 1200 | K29: =J29*G29 -> 4200
C30: RESIDENTE DE OBRA | D30: PER | E30: 1 | F30: MES | G30: 4 | H30: 3450 | I30: 1 | J30: =I30*E30*H30 -> 3450 | K30: =J30*G30 -> 13800
C31: INGENIERO SUPERVISOR MECÁNICO | D31: PER | E31: 1 | F31: MES | G31: 3.5 | H31: 3200 | I31: 1 | J31: =I31*E31*H31 -> 3200 | K31: =J31*G31 -> 11200
C32: INGENIERO SUPERVISOR ELECTRICISTA | D32: PER | E32: 1 | F32: MES | G32: 3.5 | H32: 3200 | I32: 1 | J32: =I32*E32*H32 -> 3200 | K32: =J32*G32 -> 11200
C33: INGENIERO DE CONTROL DE PROYECTOS | D33: PER | E33: 1 | F33: MES | G33: 3.5 | H33: 3200 | I33: 1 | J33: =I33*E33*H33 -> 3200 | K33: =J33*G33 -> 11200
C34: INGENIERO DE CALIDAD | D34: PER | E34: 1 | F34: MES | G34: 3.5 | H34: 3200 | I34: 1 | J34: =I34*E34*H34 -> 3200 | K34: =J34*G34 -> 11200
C35: ADMINISTRADOR DE OBRA | D35: PER | E35: 1 | F35: MES | G35: 3.5 | H35: 1550 | I35: 1 | J35: =I35*E35*H35 -> 1550 | K35: =J35*G35 -> 5425
C36: TOPOGRAFO | D36: PER | E36: 1 | F36: MES | G36: 3.5 | H36: 1750 | I36: 1 | J36: =I36*E36*H36 -> 1750 | K36: =J36*G36 -> 6125
C37: CAMIONETA | D37: UND | E37: 1 | F37: MES | G37: 4 | H37: 1450 | I37: 1 | J37: =I37*E37*H37 -> 1450 | K37: =J37*G37 -> 5800
C38: COUSTER | D38: UND | E38: 1 | F38: MES | G38: 3.5 | H38: =110*22+4*22*(3.75) -> 2750 | I38: 1 | J38: =I38*E38*H38 -> 2750 | K38: =J38*G38 -> 9625 | W38: 10KM/GAL | X38: 3 GAL/DÍA | Y38: =13.4*3 -> 40.2 | Z38: =Y38*30 -> 1206 | AA38: =Z38/3.42 -> 352.63158
C39: SPRINTER | D39: UND | E39: 1 | F39: MES | G39: 3.5 | H39: =90*22+4*22*(3.75) -> 2310 | I39: 1 | J39: =I39*E39*H39 -> 2310 | K39: =J39*G39 -> 8085 | W39: 10KM/GAL | X39: 3 GAL/DÍA | Y39: =13.4*3 -> 40.2 | Z39: =Y39*30 -> 1206 | AA39: =Z39/3.42 -> 352.63158
C40: CHOFER CAMIONETA | D40: UND | E40: 1 | F40: MES | G40: 4 | H40: 1400 | I40: 1 | J40: =I40*E40*H40 -> 1400 | K40: =J40*G40 -> 5600
C41: CHOFER DE COUSTER | D41: UND | E41: 2 | F41: MES | G41: 3.5 | H41: 1450 | I41: 1 | J41: =I41*E41*H41 -> 2900 | K41: =J41*G41 -> 10150
C42: CHOFER DE SPRINTER | D42: UND | E42: 2 | F42: MES | G42: 3.5 | H42: 1450 | I42: 1 | J42: =I42*E42*H42 -> 2900 | K42: =J42*G42 -> 10150
C43: MATERIAL DE ESCRITORIO | D43: GLB | E43: 1 | F43: MES | G43: 3.5 | H43: 200 | I43: 1 | J43: =I43*E43*H43 -> 200 | K43: =J43*G43 -> 700
C44: COMUNICACIONES | D44: GLB | E44: 1 | F44: MES | G44: 3.5 | H44: 200 | I44: 1 | J44: =I44*E44*H44 -> 200 | K44: =J44*G44 -> 700
J45: TOTAL 03 | K45: =SUM(K29:K44) -> 125160
B46: 04 CONTROL DE PERDIDAS Y MEDIO AMBIENTE
C47: INGENIERO JEFE DE SEGURIDAD | D47: PER | E47: 1 | F47: MES | G47: 4 | H47: =+H29 -> 4000 | I47: 0.3 | J47: =I47*E47*H47 -> 1200 | K47: =J47*G47 -> 4800
C48: INGENIERO DE SEGURIDAD (EHS) | D48: PER | E48: 1 | F48: MES | G48: 4 | H48: 2750 | I48: 1 | J48: =I48*E48*H48 -> 2750 | K48: =J48*G48 -> 11000
...

Sheet HH - Reg Civil
B4: RÉGIMEN CIVIL
B6: Cálculo del valor de la hora hombre | G6: Cálculo del valor de la hora hombre | L6: Cálculo del valor de la hora hombre
B7: Cálculo del valor de la hora hombre | G7: Cálculo del valor de la hora hombre | L7: Cálculo del valor de la hora hombre
B8: DESCRIPCIÓN | C8: OPERARIO | G8: DESCRIPCIÓN | H8: OFICIAL | L8: DESCRIPCIÓN | M8: AYUDANTE
C9: COND | D9: bonif | H9: COND | I9: bonif | M9: COND | N9: bonif
B10: jornal básico | C10: JB | E10: 89.3 | G10: jornal básico | H10: JB | J10: 69.75 | L10: jornal básico | M10: JB | O10: 62.8
B11: Bonificaciones | G11: Bonificaciones | L11: Bonificaciones
B12: Bonificación Unificada de Construcción BUC | C12: BUC | D12: 0.32 | E12: =D12*E10 -> 28.576 | G12: Bonificación Unificada de Construcción BUC | H12: BUC | I12: 0.3 | J12: =I12*J10 -> 20.925 | L12: Bonificación Unificada de Construcción BUC | M12: BUC | N12: 0.3 | O12: =N12*O10 -> 18.84
B13: Bonificación por Alta Especialización BAE | C13: BAE | D13: 0 | E13: =D13 -> 0 | G13: Bonificación por Alta Especialización BAE | H13: BAE | I13: 0 | J13: =I13 -> 0 | L13: Bonificación por Alta Especialización BAE | M13: BAE | N13: 0 | O13: =N13 -> 0
B14: Bonificación por Altura | C14: no | D14: 0 | E14: =D14 -> 0 | G14: Bonificación por Altura | H14: no | I14: 0 | J14: =I14 -> 0 | L14: Bonificación por Altura | M14: no | N14: 0 | O14: =N14 -> 0
B15: Bonificación por Altitud | C15: si | D15: 2 | E15: =D15 -> 2 | G15: Bonificación por Altitud | H15: si | I15: 2 | J15: =I15 -> 2 | L15: Bonificación por Altitud | M15: si | N15: 2 | O15: =N15 -> 2
B16: Bonificación por Contacto por el Agua | C16: no | D16: 0 | E16: =D16 -> 0 | G16: Bonificación por Contacto por el Agua | H16: no | I16: 0 | J16: =I16 -> 0 | L16: Bonificación por Contacto por el Agua | M16: no | N16: 0 | O16: =N16 -> 0
B17: Bonificación por Aguas Servidas | C17: no | D17: 0 | E17: =D17 -> 0 | G17: Bonificación por Aguas Servidas | H17: no | I17: 0 | J17: =I17 -> 0 | L17: Bonificación por Aguas Servidas | M17: no | N17: 0 | O17: =N17 -> 0
B18: Bonificación por Horario Nocturno | C18: NO | D18: 0 | E18: =D18 -> 0 | G18: Bonificación por Horario Nocturno | H18: NO | I18: 0 | J18: =I18 -> 0 | L18: Bonificación por Horario Nocturno | M18: NO | N18: 0 | O18: =N18 -> 0
B19: Bonificación por Movilidad | C19: si | D19: 8.6 | E19: =D19 -> 8.6 | G19: Bonificación por Movilidad | H19: si | I19: 8.6 | J19: =I19 -> 8.6 | L19: Bonificación por Movilidad | M19: si | N19: 8.6 | O19: =N19 -> 8.6
B21: Leyes Sociales | C21: RÉGIMEN | E21: SNP | G21: Leyes Sociales | H21: RÉGIMEN | J21: SNP | L21: Leyes Sociales | M21: RÉGIMEN | O21: SNP
B22: Sobre el Jornal Básico (SJB) | C22: SBJ | D22: 1.2618 | E22: =D22*E10 -> 112.67874 | G22: Sobre el Jornal Básico (SJB) | H22: SBJ | I22: =D22 -> 1.2618 | J22: =I22*J10 -> 88.01055 | L22: Sobre el Jornal Básico (SJB) | M22: SBJ | N22: =D22 -> 1.2618 | O22: =N22*O10 -> 79.24104
B23: Sobre las Bonificaciones Afectas (SBA) | C23: SBA | D23: 0.12 | E23: =D23*E12 -> 3.42912 | G23: Sobre las Bonificaciones Afectas (SBA) | H23: SBA | I23: =D23 -> 0.12 | J23: =I23*J12 -> 2.511 | L23: Sobre las Bonificaciones Afectas (SBA) | M23: SBA | N23: =D23 -> 0.12 | O23: =N23*O12 -> 2.2608
B25: overol | D25: 0.4 | E25: =D25 -> 0.4 | G25: overol | I25: 0.4 | J25: =I25 -> 0.4 | L25: overol | N25: 0.4 | O25: =N25 -> 0.4
B26: ESSALUD | D26: =0.09*E10 -> 8.037 | E26: =D26 -> 8.037 | G26: ESSALUD | I26: =0.09*J10 -> 6.2775 | J26: =I26 -> 6.2775 | L26: ESSALUD | N26: =0.09*O10 -> 5.652 | O26: =N26 -> 5.652
B28: Costo Diario (DÍA) | E28: =SUM(E22:E27)+SUM(E10:E20) -> 253.02086 | G28: Costo Diario (DÍA) | J28: =SUM(J22:J27)+SUM(J10:J20) -> 198.47405 | L28: Costo Diario (DÍA) | O28: =SUM(O22:O27)+SUM(O10:O20) -> 179.79384
B29: Costo Hora Hombre (HH) | E29: =ROUND(E28/8,2) -> 31.63 | G29: Costo Hora Hombre (HH) | J29: =ROUND(J28/8,2) -> 24.81 | L29: Costo Hora Hombre (HH) | O29: =ROUND(O28/8,2) -> 22.47
B32: OTROS COSTOS | G32: OTROS COSTOS | L32: OTROS COSTOS
B33: 9 | C33: EXAMEN MÉDICO | E33: =SUM(E34:E37)/3 -> 40 | G33: 9 | H33: EXAMEN MÉDICO | J33: =SUM(J34:J37) -> 120 | L33: 9 | M33: EXAMEN MÉDICO | O33: =SUM(O34:O37) -> 120
C34: Examen Médico Pre ocupacional x 3 meses | E34: 120 | H34: Examen Médico Pre ocupacional | J34: =E34 -> 120 | M34: Examen Médico Pre ocupacional | N34: =D34 -> 0 | O34: =E34 -> 120
C35: Examen Médico Post ocupacional x 3 meses | E35: 0 | H35: Examen Médico Post ocupacional | J35: =E35 -> 0 | M35: Examen Médico Post ocupacional | N35: =D35 -> 0 | O35: =E35 -> 0
M36: Otros exámenes (sicosensométrico, altura, mayor de 40años) | N36: =D36 -> 0 | O36: =E36 -> 0
B38: 10 | C38: EPP | E38: =SUM(E39:E39) -> 124 | G38: 10 | H38: EPP | J38: =SUM(J39:J39) -> 124 | L38: 10 | M38: EPP | O38: =SUM(O39:O39) -> 124
C39: Epp Completo x 3 meses | E39: 124 | H39: Epp Completo | I39: 1 | J39: =E39 -> 124 | M39: Epp Completo | N39: 1 | O39: =E39 -> 124
B41: 11 | C41: ALIMENTACIÓN | E41: =+E42 -> 462 | G41: 11 | H41: ALIMENTACIÓN | J41: =+J42 -> 462 | L41: 11 | M41: ALIMENTACIÓN | O41: =+O42 -> 462
C42: Alimentación (Solo almuerzo) | E42: =22*21 -> 462 | H42: Alimentación (Solo almuerzo) | J42: =E42 -> 462 | M42: Alimentación (Solo almuerzo) | O42: =E42 -> 462
B43: 12 | C43: TRANSPORTE | E43: =+E44 -> 0 | G43: 12 | H43: TRANSPORTE | J43: =+J44 -> 0 | L43: 12 | M43: TRANSPORTE | O43: =+O44 -> 0
C44: Transporte | E44: 0 | H44: Transporte | J44: =E44 -> 0 | M44: Transporte | O44: =E44 -> 0
B45: 13 | C45: CURSOS DE CAPACITACIÓN | E45: =SUM(E46:E48) -> 60 | G45: 13 | H45: CURSOS DE CAPACITACIÓN | J45: =SUM(J46:J48) -> 60 | L45: 13 | M45: CURSOS DE CAPACITACIÓN | O45: =SUM(O46:O48) -> 60
C46: inducción x 3 meses | E46: 60 | H46: inducción | J46: =E46 -> 60 | M46: inducción | O46: =E46 -> 60
C48: cursos mensuales (01 curso por mes) | E48: 0 | H48: cursos mensuales (01 curso por mes) | J48: =E48 -> 0 | M48: cursos mensuales (01 curso por mes) | O48: =E48 -> 0
B50: 14 | C50: BONIFICACIÓN EXTRAORDINARIA POR PRODUCCIÓN. | E50: 200 | G50: 14 | H50: BONIFICACIÓN EXTRAORDINARIA POR PRODUCCIÓN. | J50: 150 | L50: 14 | M50: BONIFICACIÓN EXTRAORDINARIA POR PRODUCCIÓN. | O50: 100
B51: 15 | G51: 15 | L51: 15
B52: OTROS COSTOS MESES (PLAZO, modificable a duración de obra) | D52: 4 | E52: =+E45+E41+E38+E33+E43+E50 -> 886 | G52: OTROS COSTOS MESES (PLAZO, modificable a duración de obra) | I52: 4 | J52: =+J45+J41+J38+J33+J43+J50 -> 916 | L52: OTROS COSTOS MESES (PLAZO, modificable a duración de obra) | N52: 4 | O52: =+O45+O41+O38+O33+O43+O50 -> 866
B53: TASA DE CAMBIO | D53: 3.5 | G53: TASA DE CAMBIO | I53: =D53 -> 3.5 | L53: TASA DE CAMBIO | N53: =D53 -> 3.5
...

Sheet HH - Reg. común
D2: CAPATAZ ELECTRICISTA | E2: TC | F2: 3.5 | I2: CAPATAZ | J2: TC | K2: 3.5 | N2: SOLDADOR 4G | O2: TC | P2: 3.5
C3: ITEM | D3: DESCRIPCION | E3: % | H3: ITEM | I3: DESCRIPCION | J3: % | M3: ITEM | N3: DESCRIPCION | O3: %
C4: COSTOS MENSUALES REFERENCIALES | H4: COSTOS MENSUALES REFERENCIALES | M4: COSTOS MENSUALES REFERENCIALES
C5: 1 | D5: SUELDO BRUTO | F5: =+F6+F7 -> 4613 | H5: 1 | I5: SUELDO BRUTO | K5: =+K6+K7 -> 4613 | M5: 1 | N5: SUELDO BRUTO | P5: =+P6+P7 -> 5113
D6: Haber básico mensual | E6: - | F6: 4500 | I6: Haber básico mensual | J6: - | K6: 4500 | N6: Haber básico mensual | O6: - | P6: 5000
D7: Asignación familiar | E7: - | F7: 113 | I7: Asignación familiar | J7: - | K7: 113 | N7: Asignación familiar | O7: - | P7: =+K7 -> 113
C8: 2 | D8: AFP | F8: =SUM(F9:F11) -> 599.69 | H8: 2 | I8: AFP | K8: =SUM(K9:K11) -> 599.69 | M8: 2 | N8: AFP | P8: =SUM(P9:P11) -> 664.69
D9: Aporte obligatorio 10% | E9: 10 | F9: =+F5*$E9/100 -> 461.3 | I9: Aporte obligatorio 10% | J9: 10 | K9: =+K5*$E9/100 -> 461.3 | N9: Aporte obligatorio 10% | O9: 10 | P9: =+P5*$E9/100 -> 511.3
D10: Prima de seguro 1.23% | E10: 1.23 | F10: =+F5*$E10/100 -> 56.7399 | I10: Prima de seguro 1.23% | J10: 1.23 | K10: =+K5*$E10/100 -> 56.7399 | N10: Prima de seguro 1.23% | O10: 1.23 | P10: =+P5*$E10/100 -> 62.8899
